Workbook

Sheet AP01
A1: APÊNDICE 01: EVOLUÇÃO DO FINANCIAMENTO COBRADO PELO BANCO
A3: Requerente: ADRIANA MELO DE OLIVEIRA
A4: Requerido: ITAÚ UNIBANCO
A5: Valor do Bem | D5: 432000 | F5: Qtde Prestações | I5: 360 | X5: =S7 -> 31402
A6: Entrada/Descontos | D6: 129600 | F6: Taxa de Juros Efetiva (a.m.) | I6: =((1+I7)^(1/12))-1 -> 0.0092631835 | W6: 1 | X6: =EDATE(X5,12) -> 31767
A7: Valor Financiado | D7: =D5-D6 -> 302400 | F7: Taxa de Juros Efetiva (a.a.) | I7: 0.117 | R7: Data Nasc | S7: 31402 | W7: =W6+1 -> 2 | X7: =EDATE(X6,12) -> 32132
A8: Data do Contrato | D8: 43241 | F8: Taxa de Juros com benfício (a.m.) | I8: =((1+I9)^(1/12))-1 -> 0.0056541454 | W8: =W7+1 -> 3 | X8: =EDATE(X7,12) -> 32498
A9: 1° Vencimento | D9: 43272 | F9: Taxa de Juros com benfício (a.a.) | I9: 0.07 | W9: =W8+1 -> 4 | X9: =EDATE(X8,12) -> 32863
A10: Sistema de Amortização | D10: SAC | F10: Prestação Mensal | I10: =(D7/I5)+(D7*I8) -> 2549.8136 | W10: =W9+1 -> 5 | X10: =EDATE(X9,12) -> 33228
A11: Índice Correção | D11: TR | F11: Enquadramento | I11: SFH | W11: =W10+1 -> 6 | X11: =EDATE(X10,12) -> 33593
W12: =W11+1 -> 7 | X12: =EDATE(X11,12) -> 33959
A13: Qtde | B13: Data Vencimento | C13: Taxa Efetiva a.a. | D13: Taxa Efetiva a.m. | E13: Prestação (a+j) | F13: Juros | G13: Amortização | H13: Seguro MIP | I13: Seguro DFI | J13: TCA | K13: Multa | L13: Mora | M13: Total da Parcela | N13: Correção Monetária | O13: Saldo Devedor | P13: Índice Correção | Q13: Valor Garantia | R13: Idade | S13: % MIP | T13: Seguro DFI2 | U13: Seguro MIP2 | W13: =W12+1 -> 8 | X13: =EDATE(X12,12) -> 34324
A14: 0 | B14: =D8 -> 43241 | O14: =D7 -> 302400 | Q14: 432000 | R14: =DATEDIF($S$7,'AP01'!$B14,"Y") -> 32 | S14: =VLOOKUP('AP01'!$R14,SEGUROS!$A:$B,2,TRUE) -> 0.0001381 | T14: ='AP01'!$O14*'AP01'!$S14 -> 41.76144 | U14: ='AP01'!$Q14*0.00899% -> 38.8368 | W14: =W13+1 -> 9 | X14: =EDATE(X13,12) -> 34689
A15: =A14+1 -> 1 | B15: =D9 -> 43272 | C15: =I9 -> 0.07 | D15: 0.005654 | E15: ='AP01'!$F15+'AP01'!$G15 -> 2549.76 | F15: 1709.76 | G15: =(O14*'AP01'!$P15)/($I$5-A14) -> 840 | H15: 62.54 | I15: 77.66 | J15: 25 | K15: 0 | L15: 0 | M15: =SUM('AP01'!$F15:$L15) -> 2714.96 | N15: =O14*('AP01'!$P15-1) -> 0 | O15: =(O14*'AP01'!$P15)-'AP01'!$G15 -> 301560 | P15: 1 | Q15: =(Q14*'AP01'!$P15) -> 432000 | R15: =DATEDIF($S$7,'AP01'!$B15,"Y") -> 32 | S15: =VLOOKUP('AP01'!$R15,SEGUROS!$A:$B,2,TRUE) -> 0.0001381 | T15: =('AP01'!$O15*'AP01'!$P15)*'AP01'!$S15 -> 41.645436 | U15: ='AP01'!$Q15*0.00899% -> 38.8368 | W15: =W14+1 -> 10 | X15: =EDATE(X14,12) -> 35054 | Z15: =H16/O16 -> 0.00010371774
A16: =A15+1 -> 2 | B16: =EDATE(B15,1) -> 43302 | C16: =C15 -> 0.07 | D16: =D15 -> 0.005654 | E16: ='AP01'!$F16+'AP01'!$G16 -> 2545.02 | F16: 1705.02 | G16: =(O15*'AP01'!$P16)/($I$5-A15) -> 840 | H16: 31.19 | I16: 38.83 | J16: =J15 -> 25 | K16: =K15 -> 0 | L16: =L15 -> 0 | M16: =SUM('AP01'!$F16:$L16) -> 2640.04 | N16: =O15*('AP01'!$P16-1) -> 0 | O16: =(O15*'AP01'!$P16)-'AP01'!$G16 -> 300720 | P16: =P15 -> 1 | Q16: =(Q15*'AP01'!$P16) -> 432000 | R16: =DATEDIF($S$7,'AP01'!$B16,"Y") -> 32 | S16: =VLOOKUP('AP01'!$R16,SEGUROS!$A:$B,2,TRUE) -> 0.0001381 | T16: =('AP01'!$O16*'AP01'!$P16)*'AP01'!$S16 -> 41.529432 | U16: ='AP01'!$Q16*0.00899% -> 38.8368 | W16: =W15+1 -> 11 | X16: =EDATE(X15,12) -> 35420 | Z16: =H17/O17 -> 0.00010370815
A17: =A16+1 -> 3 | B17: =EDATE(B16,1) -> 43333 | C17: =C16 -> 0.07 | D17: =D16 -> 0.005654 | E17: ='AP01'!$F17+'AP01'!$G17 -> 2540.27 | F17: 1700.27 | G17: =(O16*'AP01'!$P17)/($I$5-A16) -> 840 | H17: 31.1 | I17: 38.83 | J17: =J16 -> 25 | K17: =K16 -> 0 | L17: =L16 -> 0 | M17: =SUM('AP01'!$F17:$L17) -> 2635.2 | N17: =O16*('AP01'!$P17-1) -> 0 | O17: =(O16*'AP01'!$P17)-'AP01'!$G17 -> 299880 | P17: =P16 -> 1 | Q17: =(Q16*'AP01'!$P17) -> 432000 | R17: =DATEDIF($S$7,'AP01'!$B17,"Y") -> 32 | S17: =VLOOKUP('AP01'!$R17,SEGUROS!$A:$B,2,TRUE) -> 0.0001381 | T17: =('AP01'!$O17*'AP01'!$P17)*'AP01'!$S17 -> 41.413428 | U17: ='AP01'!$Q17*0.00899% -> 38.8368 | W17: =W16+1 -> 12 | X17: =EDATE(X16,12) -> 35785 | Z17: =H18/O18 -> 0.0001036985
A18: =A17+1 -> 4 | B18: =EDATE(B17,1) -> 43364 | C18: =C17 -> 0.07 | D18: =D17 -> 0.005654 | E18: ='AP01'!$F18+'AP01'!$G18 -> 2535.52 | F18: 1695.52 | G18: =(O17*'AP01'!$P18)/($I$5-A17) -> 840 | H18: 31.01 | I18: 38.83 | J18: =J17 -> 25 | K18: =K17 -> 0 | L18: =L17 -> 0 | M18: =SUM('AP01'!$F18:$L18) -> 2630.36 | N18: =O17*('AP01'!$P18-1) -> 0 | O18: =(O17*'AP01'!$P18)-'AP01'!$G18 -> 299040 | P18: =P17 -> 1 | Q18: =(Q17*'AP01'!$P18) -> 432000 | R18: =DATEDIF($S$7,'AP01'!$B18,"Y") -> 32 | S18: =VLOOKUP('AP01'!$R18,SEGUROS!$A:$B,2,TRUE) -> 0.0001381 | T18: =('AP01'!$O18*'AP01'!$P18)*'AP01'!$S18 -> 41.297424 | U18: ='AP01'!$Q18*0.00899% -> 38.8368 | W18: =W17+1 -> 13 | X18: =EDATE(X17,12) -> 36150 | Z18: =H19/O19 -> 0.0001036888
A19: =A18+1 -> 5 | B19: =EDATE(B18,1) -> 43394 | C19: =C18 -> 0.07 | D19: =D18 -> 0.005654 | E19: ='AP01'!$F19+'AP01'!$G19 -> 2530.77 | F19: 1690.77 | G19: =(O18*'AP01'!$P19)/($I$5-A18) -> 840 | H19: 30.92 | I19: 38.83 | J19: =J18 -> 25 | K19: =K18 -> 0 | L19: =L18 -> 0 | M19: =SUM('AP01'!$F19:$L19) -> 2625.52 | N19: =O18*('AP01'!$P19-1) -> 0 | O19: =(O18*'AP01'!$P19)-'AP01'!$G19 -> 298200 | P19: =P18 -> 1 | Q19: =(Q18*'AP01'!$P19) -> 432000 | R19: =DATEDIF($S$7,'AP01'!$B19,"Y") -> 32 | S19: =VLOOKUP('AP01'!$R19,SEGUROS!$A:$B,2,TRUE) -> 0.0001381 | T19: =('AP01'!$O19*'AP01'!$P19)*'AP01'!$S19 -> 41.18142 | U19: ='AP01'!$Q19*0.00899% -> 38.8368 | W19: =W18+1 -> 14 | X19: =EDATE(X18,12) -> 36515 | Z19: =H20/O20 -> 0.00010371267
A20: =A19+1 -> 6 | B20: =EDATE(B19,1) -> 43425 | C20: =C19 -> 0.07 | D20: =D19 -> 0.005654 | E20: ='AP01'!$F20+'AP01'!$G20 -> 2526.02 | F20: 1686.02 | G20: =(O19*'AP01'!$P20)/($I$5-A19) -> 840 | H20: 30.84 | I20: 38.83 | J20: =J19 -> 25 | K20: =K19 -> 0 | L20: =L19 -> 0 | M20: =SUM('AP01'!$F20:$L20) -> 2620.69 | N20: =O19*('AP01'!$P20-1) -> 0 | O20: =(O19*'AP01'!$P20)-'AP01'!$G20 -> 297360 | P20: =P19 -> 1 | Q20: =(Q19*'AP01'!$P20) -> 432000 | R20: =DATEDIF($S$7,'AP01'!$B20,"Y") -> 32 | S20: =VLOOKUP('AP01'!$R20,SEGUROS!$A:$B,2,TRUE) -> 0.0001381 | T20: =('AP01'!$O20*'AP01'!$P20)*'AP01'!$S20 -> 41.065416 | U20: ='AP01'!$Q20*0.00899% -> 38.8368 | W20: =W19+1 -> 15 | X20: =EDATE(X19,12) -> 36881 | Z20: =H21/O21 -> 0.00010559153
A21: =A20+1 -> 7 | B21: =EDATE(B20,1) -> 43455 | C21: =C20 -> 0.07 | D21: =D20 -> 0.005654 | E21: ='AP01'!$F21+'AP01'!$G21 -> 2521.27 | F21: 1681.27 | G21: =(O20*'AP01'!$P21)/($I$5-A20) -> 840 | H21: 31.31 | I21: 38.83 | J21: =J20 -> 25 | K21: =K20 -> 0 | L21: =L20 -> 0 | M21: =SUM('AP01'!$F21:$L21) -> 2616.41 | N21: =O20*('AP01'!$P21-1) -> 0 | O21: =(O20*'AP01'!$P21)-'AP01'!$G21 -> 296520 | P21: =P20 -> 1 | Q21: =(Q20*'AP01'!$P21) -> 432000 | R21: =DATEDIF($S$7,'AP01'!$B21,"Y") -> 33 | S21: =VLOOKUP('AP01'!$R21,SEGUROS!$A:$B,2,TRUE) -> 0.0001423 | T21: =('AP01'!$O21*'AP01'!$P21)*'AP01'!$S21 -> 42.194796 | U21: ='AP01'!$Q21*0.00899% -> 38.8368 | W21: =W20+1 -> 16 | X21: =EDATE(X20,12) -> 37246 | Z21: =H22/O22 -> 0.00010558712
A22: =A21+1 -> 8 | B22: =EDATE(B21,1) -> 43486 | C22: =C21 -> 0.07 | D22: =D21 -> 0.005654 | E22: ='AP01'!$F22+'AP01'!$G22 -> 2516.52 | F22: 1676.52 | G22: =(O21*'AP01'!$P22)/($I$5-A21) -> 840 | H22: 31.22 | I22: 38.83 | J22: =J21 -> 25 | K22: =K21 -> 0 | L22: =L21 -> 0 | M22: =SUM('AP01'!$F22:$L22) -> 2611.57 | N22: =O21*('AP01'!$P22-1) -> 0 | O22: =(O21*'AP01'!$P22)-'AP01'!$G22 -> 295680 | P22: =P21 -> 1 | Q22: =(Q21*'AP01'!$P22) -> 432000 | R22: =DATEDIF($S$7,'AP01'!$B22,"Y") -> 33 | S22: =VLOOKUP('AP01'!$R22,SEGUROS!$A:$B,2,TRUE) -> 0.0001423 | T22: =('AP01'!$O22*'AP01'!$P22)*'AP01'!$S22 -> 42.075264 | U22: ='AP01'!$Q22*0.00899% -> 38.8368 | W22: =W21+1 -> 17 | X22: =EDATE(X21,12) -> 37611 | Z22: =H23/O23 -> 0.00010558269
A23: =A22+1 -> 9 | B23: =EDATE(B22,1) -> 43517 | C23: =C22 -> 0.07 | D23: =D22 -> 0.005654 | E23: ='AP01'!$F23+'AP01'!$G23 -> 2511.77 | F23: 1671.77 | G23: =(O22*'AP01'!$P23)/($I$5-A22) -> 840 | H23: 31.13 | I23: 38.83 | J23: =J22 -> 25 | K23: =K22 -> 0 | L23: =L22 -> 0 | M23: =SUM('AP01'!$F23:$L23) -> 2606.73 | N23: =O22*('AP01'!$P23-1) -> 0 | O23: =(O22*'AP01'!$P23)-'AP01'!$G23 -> 294840 | P23: =P22 -> 1 | Q23: =(Q22*'AP01'!$P23) -> 432000 | R23: =DATEDIF($S$7,'AP01'!$B23,"Y") -> 33 | S23: =VLOOKUP('AP01'!$R23,SEGUROS!$A:$B,2,TRUE) -> 0.0001423 | T23: =('AP01'!$O23*'AP01'!$P23)*'AP01'!$S23 -> 41.955732 | U23: ='AP01'!$Q23*0.00899% -> 38.8368 | W23: =W22+1 -> 18 | X23: =EDATE(X22,12) -> 37976 | Z23: =H24/O24 -> 0.00010557823
A24: =A23+1 -> 10 | B24: =EDATE(B23,1) -> 43545 | C24: =C23 -> 0.07 | D24: =D23 -> 0.005654 | E24: ='AP01'!$F24+'AP01'!$G24 -> 2507.02 | F24: 1667.02 | G24: =(O23*'AP01'!$P24)/($I$5-A23) -> 840 | H24: 31.04 | I24: 38.83 | J24: =J23 -> 25 | K24: =K23 -> 0 | L24: =L23 -> 0 | M24: =SUM('AP01'!$F24:$L24) -> 2601.89 | N24: =O23*('AP01'!$P24-1) -> 0 | O24: =(O23*'AP01'!$P24)-'AP01'!$G24 -> 294000 | P24: =P23 -> 1 | Q24: =(Q23*'AP01'!$P24) -> 432000 | R24: =DATEDIF($S$7,'AP01'!$B24,"Y") -> 33 | S24: =VLOOKUP('AP01'!$R24,SEGUROS!$A:$B,2,TRUE) -> 0.0001423 | T24: =('AP01'!$O24*'AP01'!$P24)*'AP01'!$S24 -> 41.8362 | U24: ='AP01'!$Q24*0.00899% -> 38.8368 | W24: =W23+1 -> 19 | X24: =EDATE(X23,12) -> 38342 | Z24: =H25/O25 -> 0.00010557375
A25: =A24+1 -> 11 | B25: =EDATE(B24,1) -> 43576 | C25: =C24 -> 0.07 | D25: =D24 -> 0.005654 | E25: ='AP01'!$F25+'AP01'!$G25 -> 2502.27 | F25: 1662.27 | G25: =(O24*'AP01'!$P25)/($I$5-A24) -> 840 | H25: 30.95 | I25: 38.83 | J25: =J24 -> 25 | K25: =K24 -> 0 | L25: =L24 -> 0 | M25: =SUM('AP01'!$F25:$L25) -> 2597.05 | N25: =O24*('AP01'!$P25-1) -> 0 | O25: =(O24*'AP01'!$P25)-'AP01'!$G25 -> 293160 | P25: =P24 -> 1 | Q25: =(Q24*'AP01'!$P25) -> 432000 | R25: =DATEDIF($S$7,'AP01'!$B25,"Y") -> 33 | S25: =VLOOKUP('AP01'!$R25,SEGUROS!$A:$B,2,TRUE) -> 0.0001423 | T25: =('AP01'!$O25*'AP01'!$P25)*'AP01'!$S25 -> 41.716668 | U25: ='AP01'!$Q25*0.00899% -> 38.8368 | W25: =W24+1 -> 20 | X25: =EDATE(X24,12) -> 38707 | Z25: =H26/O26 -> 0.00010556924
A26: =A25+1 -> 12 | B26: =EDATE(B25,1) -> 43606 | C26: =C25 -> 0.07 | D26: =D25 -> 0.005654 | E26: ='AP01'!$F26+'AP01'!$G26 -> 2497.52 | F26: 1657.52 | G26: =(O25*'AP01'!$P26)/($I$5-A25) -> 840 | H26: 30.86 | I26: 38.83 | J26: =J25 -> 25 | K26: =K25 -> 0 | L26: =L25 -> 0 | M26: =SUM('AP01'!$F26:$L26) -> 2592.21 | N26: =O25*('AP01'!$P26-1) -> 0 | O26: =(O25*'AP01'!$P26)-'AP01'!$G26 -> 292320 | P26: =P25 -> 1 | Q26: =(Q25*'AP01'!$P26) -> 432000 | R26: =DATEDIF($S$7,'AP01'!$B26,"Y") -> 33 | S26: =VLOOKUP('AP01'!$R26,SEGUROS!$A:$B,2,TRUE) -> 0.0001423 | T26: =('AP01'!$O26*'AP01'!$P26)*'AP01'!$S26 -> 41.597136 | U26: ='AP01'!$Q26*0.00899% -> 38.8368 | W26: =W25+1 -> 21 | X26: =EDATE(X25,12) -> 39072 | Z26: =H27/O27 -> 0.00010559901
A27: =A26+1 -> 13 | B27: =EDATE(B26,1) -> 43637 | C27: =C26 -> 0.07 | D27: =D26 -> 0.005654 | E27: ='AP01'!$F27+'AP01'!$G27 -> 2492.77 | F27: 1652.77 | G27: =(O26*'AP01'!$P27)/($I$5-A26) -> 840 | H27: 30.78 | I27: 38.83 | J27: =J26 -> 25 | K27: =K26 -> 0 | L27: =L26 -> 0 | M27: =SUM('AP01'!$F27:$L27) -> 2587.38 | N27: =O26*('AP01'!$P27-1) -> 0 | O27: =(O26*'AP01'!$P27)-'AP01'!$G27 -> 291480 | P27: =P26 -> 1 | Q27: =(Q26*'AP01'!$P27) -> 432000 | R27: =DATEDIF($S$7,'AP01'!$B27,"Y") -> 33 | S27: =VLOOKUP('AP01'!$R27,SEGUROS!$A:$B,2,TRUE) -> 0.0001423 | T27: =('AP01'!$O27*'AP01'!$P27)*'AP01'!$S27 -> 41.477604 | U27: ='AP01'!$Q27*0.00899% -> 38.8368 | W27: =W26+1 -> 22 | X27: =EDATE(X26,12) -> 39437 | Z27: =H28/O28 -> 0.00010559455
A28: =A27+1 -> 14 | B28: =EDATE(B27,1) -> 43667 | C28: =C27 -> 0.07 | D28: =D27 -> 0.005654 | E28: ='AP01'!$F28+'AP01'!$G28 -> 2488.02 | F28: 1648.02 | G28: =(O27*'AP01'!$P28)/($I$5-A27) -> 840 | H28: 30.69 | I28: 38.83 | J28: =J27 -> 25 | K28: =K27 -> 0 | L28: =L27 -> 0 | M28: =SUM('AP01'!$F28:$L28) -> 2582.54 | N28: =O27*('AP01'!$P28-1) -> 0 | O28: =(O27*'AP01'!$P28)-'AP01'!$G28 -> 290640 | P28: =P27 -> 1 | Q28: =(Q27*'AP01'!$P28) -> 432000 | R28: =DATEDIF($S$7,'AP01'!$B28,"Y") -> 33 | S28: =VLOOKUP('AP01'!$R28,SEGUROS!$A:$B,2,TRUE) -> 0.0001423 | T28: =('AP01'!$O28*'AP01'!$P28)*'AP01'!$S28 -> 41.358072 | U28: ='AP01'!$Q28*0.00899% -> 38.8368 | W28: =W27+1 -> 23 | X28: =EDATE(X27,12) -> 39803
A29: =A28+1 -> 15 | B29: =EDATE(B28,1) -> 43698 | C29: =C28 -> 0.07 | D29: =D28 -> 0.005654 | E29: ='AP01'!$F29+'AP01'!$G29 -> 2483.27 | F29: 1643.27 | G29: =(O28*'AP01'!$P29)/($I$5-A28) -> 840 | H29: 30.6 | I29: 38.83 | J29: =J28 -> 25 | K29: =K28 -> 0 | L29: =L28 -> 0 | M29: =SUM('AP01'!$F29:$L29) -> 2577.7 | N29: =O28*('AP01'!$P29-1) -> 0 | O29: =(O28*'AP01'!$P29)-'AP01'!$G29 -> 289800 | P29: =P28 -> 1 | Q29: =(Q28*'AP01'!$P29) -> 432000 | R29: =DATEDIF($S$7,'AP01'!$B29,"Y") -> 33 | S29: =VLOOKUP('AP01'!$R29,SEGUROS!$A:$B,2,TRUE) -> 0.0001423 | T29: =('AP01'!$O29*'AP01'!$P29)*'AP01'!$S29 -> 41.23854 | U29: ='AP01'!$Q29*0.00899% -> 38.8368 | W29: =W28+1 -> 24 | X29: =EDATE(X28,12) -> 40168
A30: =A29+1 -> 16 | B30: =EDATE(B29,1) -> 43729 | C30: =C29 -> 0.07 | D30: =D29 -> 0.005654 | E30: ='AP01'!$F30+'AP01'!$G30 -> 2478.52 | F30: 1638.52 | G30: =(O29*'AP01'!$P30)/($I$5-A29) -> 840 | H30: 30.51 | I30: 38.83 | J30: =J29 -> 25 | K30: =K29 -> 0 | L30: =L29 -> 0 | M30: =SUM('AP01'!$F30:$L30) -> 2572.86 | N30: =O29*('AP01'!$P30-1) -> 0 | O30: =(O29*'AP01'!$P30)-'AP01'!$G30 -> 288960 | P30: =P29 -> 1 | Q30: =(Q29*'AP01'!$P30) -> 432000 | R30: =DATEDIF($S$7,'AP01'!$B30,"Y") -> 33 | S30: =VLOOKUP('AP01'!$R30,SEGUROS!$A:$B,2,TRUE) -> 0.0001423 | T30: =('AP01'!$O30*'AP01'!$P30)*'AP01'!$S30 -> 41.119008 | U30: ='AP01'!$Q30*0.00899% -> 38.8368 | W30: =W29+1 -> 25 | X30: =EDATE(X29,12) -> 40533
A31: =A30+1 -> 17 | B31: =EDATE(B30,1) -> 43759 | C31: =C30 -> 0.07 | D31: =D30 -> 0.005654 | E31: ='AP01'!$F31+'AP01'!$G31 -> 2473.77 | F31: 1633.77 | G31: =(O30*'AP01'!$P31)/($I$5-A30) -> 840 | H31: 30.42 | I31: 38.83 | J31: =J30 -> 25 | K31: =K30 -> 0 | L31: =L30 -> 0 | M31: =SUM('AP01'!$F31:$L31) -> 2568.02 | N31: =O30*('AP01'!$P31-1) -> 0 | O31: =(O30*'AP01'!$P31)-'AP01'!$G31 -> 288120 | P31: =P30 -> 1 | Q31: =(Q30*'AP01'!$P31) -> 432000 | R31: =DATEDIF($S$7,'AP01'!$B31,"Y") -> 33 | S31: =VLOOKUP('AP01'!$R31,SEGUROS!$A:$B,2,TRUE) -> 0.0001423 | T31: =('AP01'!$O31*'AP01'!$P31)*'AP01'!$S31 -> 40.999476 | U31: ='AP01'!$Q31*0.00899% -> 38.8368 | W31: =W30+1 -> 26 | X31: =EDATE(X30,12) -> 40898
A32: =A31+1 -> 18 | B32: =EDATE(B31,1) -> 43790 | C32: =C31 -> 0.07 | D32: =D31 -> 0.005654 | E32: ='AP01'!$F32+'AP01'!$G32 -> 2469.03 | F32: 1629.03 | G32: =(O31*'AP01'!$P32)/($I$5-A31) -> 840 | H32: 30.33 | I32: 38.83 | J32: =J31 -> 25 | K32: =K31 -> 0 | L32: =L31 -> 0 | M32: =SUM('AP01'!$F32:$L32) -> 2563.19 | N32: =O31*('AP01'!$P32-1) -> 0 | O32: =(O31*'AP01'!$P32)-'AP01'!$G32 -> 287280 | P32: =P31 -> 1 | Q32: =(Q31*'AP01'!$P32) -> 432000 | R32: =DATEDIF($S$7,'AP01'!$B32,"Y") -> 33 | S32: =VLOOKUP('AP01'!$R32,SEGUROS!$A:$B,2,TRUE) -> 0.0001423 | T32: =('AP01'!$O32*'AP01'!$P32)*'AP01'!$S32 -> 40.879944 | U32: ='AP01'!$Q32*0.00899% -> 38.8368 | W32: =W31+1 -> 27 | X32: =EDATE(X31,12) -> 41264
A33: =A32+1 -> 19 | B33: =EDATE(B32,1) -> 43820 | C33: =C32 -> 0.07 | D33: =D32 -> 0.005654 | E33: ='AP01'!$F33+'AP01'!$G33 -> 2464.28 | F33: 1624.28 | G33: =(O32*'AP01'!$P33)/($I$5-A32) -> 840 | H33: 30.87 | I33: 38.83 | J33: =J32 -> 25 | K33: =K32 -> 0 | L33: =L32 -> 0 | M33: =SUM('AP01'!$F33:$L33) -> 2558.98 | N33: =O32*('AP01'!$P33-1) -> 0 | O33: =(O32*'AP01'!$P33)-'AP01'!$G33 -> 286440 | P33: =P32 -> 1 | Q33: =(Q32*'AP01'!$P33) -> 432000 | R33: =DATEDIF($S$7,'AP01'!$B33,"Y") -> 34 | S33: =VLOOKUP('AP01'!$R33,SEGUROS!$A:$B,2,TRUE) -> 0.0001472 | T33: =('AP01'!$O33*'AP01'!$P33)*'AP01'!$S33 -> 42.163968 | U33: ='AP01'!$Q33*0.00899% -> 38.8368 | W33: =W32+1 -> 28 | X33: =EDATE(X32,12) -> 41629
A34: =A33+1 -> 20 | B34: =EDATE(B33,1) -> 43851 | C34: =C33 -> 0.07 | D34: =D33 -> 0.005654 | E34: ='AP01'!$F34+'AP01'!$G34 -> 2459.53 | F34: 1619.53 | G34: =(O33*'AP01'!$P34)/($I$5-A33) -> 840 | H34: 30.78 | I34: 38.83 | J34: =J33 -> 25 | K34: =K33 -> 0 | L34: =L33 -> 0 | M34: =SUM('AP01'!$F34:$L34) -> 2554.14 | N34: =O33*('AP01'!$P34-1) -> 0 | O34: =(O33*'AP01'!$P34)-'AP01'!$G34 -> 285600 | P34: =P33 -> 1 | Q34: =(Q33*'AP01'!$P34) -> 432000 | R34: =DATEDIF($S$7,'AP01'!$B34,"Y") -> 34 | S34: =VLOOKUP('AP01'!$R34,SEGUROS!$A:$B,2,TRUE) -> 0.0001472 | T34: =('AP01'!$O34*'AP01'!$P34)*'AP01'!$S34 -> 42.04032 | U34: ='AP01'!$Q34*0.00899% -> 38.8368 | W34: =W33+1 -> 29 | X34: =EDATE(X33,12) -> 41994
A35: =A34+1 -> 21 | B35: =EDATE(B34,1) -> 43882 | C35: =C34 -> 0.07 | D35: =D34 -> 0.005654 | E35: ='AP01'!$F35+'AP01'!$G35 -> 2454.78 | F35: 1614.78 | G35: =(O34*'AP01'!$P35)/($I$5-A34) -> 840 | H35: 39.94 | I35: 38.83 | J35: =J34 -> 25 | K35: =K34 -> 0 | L35: =L34 -> 0 | M35: =SUM('AP01'!$F35:$L35) -> 2558.55 | N35: =O34*('AP01'!$P35-1) -> 0 | O35: =(O34*'AP01'!$P35)-'AP01'!$G35 -> 284760 | P35: =P34 -> 1 | Q35: =(Q34*'AP01'!$P35) -> 432000 | R35: =DATEDIF($S$7,'AP01'!$B35,"Y") -> 34 | S35: =VLOOKUP('AP01'!$R35,SEGUROS!$A:$B,2,TRUE) -> 0.0001472 | T35: =('AP01'!$O35*'AP01'!$P35)*'AP01'!$S35 -> 41.916672 | U35: ='AP01'!$Q35*0.00899% -> 38.8368
A36: =A35+1 -> 22 | B36: =EDATE(B35,1) -> 43911 | C36: 0.062 | D36: 0.005025 | E36: ='AP01'!$F36+'AP01'!$G36 -> 2270.91 | F36: 1430.91 | G36: =(O35*'AP01'!$P36)/($I$5-A35) -> 840 | H36: 39.82 | I36: 38.83 | J36: =J35 -> 25 | K36: =K35 -> 0 | L36: =L35 -> 0 | M36: =SUM('AP01'!$F36:$L36) -> 2374.56 | N36: =O35*('AP01'!$P36-1) -> 0 | O36: =(O35*'AP01'!$P36)-'AP01'!$G36 -> 283920 | P36: =P35 -> 1 | Q36: =(Q35*'AP01'!$P36) -> 432000 | R36: =DATEDIF($S$7,'AP01'!$B36,"Y") -> 34 | S36: =VLOOKUP('AP01'!$R36,SEGUROS!$A:$B,2,TRUE) -> 0.0001472 | T36: =('AP01'!$O36*'AP01'!$P36)*'AP01'!$S36 -> 41.793024 | U36: ='AP01'!$Q36*0.00899% -> 38.8368
A37: =A36+1 -> 23 | B37: =EDATE(B36,1) -> 43942 | C37: 0.062 | D37: =D36 -> 0.005025 | E37: ='AP01'!$F37+'AP01'!$G37 -> 2266.69 | F37: 1426.69 | G37: =(O36*'AP01'!$P37)/($I$5-A36) -> 840 | H37: 39.71 | I37: 38.83 | J37: =J36 -> 25 | K37: =K36 -> 0 | L37: =L36 -> 0 | M37: =SUM('AP01'!$F37:$L37) -> 2370.23 | N37: =O36*('AP01'!$P37-1) -> 0 | O37: =(O36*'AP01'!$P37)-'AP01'!$G37 -> 283080 | P37: =P36 -> 1 | Q37: =(Q36*'AP01'!$P37) -> 432000 | R37: =DATEDIF($S$7,'AP01'!$B37,"Y") -> 34 | S37: =VLOOKUP('AP01'!$R37,SEGUROS!$A:$B,2,TRUE) -> 0.0001472 | T37: =('AP01'!$O37*'AP01'!$P37)*'AP01'!$S37 -> 41.669376 | U37: ='AP01'!$Q37*0.00899% -> 38.8368
A38: =A37+1 -> 24 | B38: =EDATE(B37,1) -> 43972 | C38: 0.062 | D38: =D37 -> 0.005025 | E38: ='AP01'!$F38+'AP01'!$G38 -> 2262.47 | F38: 1422.47 | G38: =(O37*'AP01'!$P38)/($I$5-A37) -> 840 | H38: 39.59 | I38: 38.83 | J38: =J37 -> 25 | K38: =K37 -> 0 | L38: =L37 -> 0 | M38: =SUM('AP01'!$F38:$L38) -> 2365.89 | N38: =O37*('AP01'!$P38-1) -> 0 | O38: =(O37*'AP01'!$P38)-'AP01'!$G38 -> 282240 | P38: =P37 -> 1 | Q38: =(Q37*'AP01'!$P38) -> 432000 | R38: =DATEDIF($S$7,'AP01'!$B38,"Y") -> 34 | S38: =VLOOKUP('AP01'!$R38,SEGUROS!$A:$B,2,TRUE) -> 0.0001472 | T38: =('AP01'!$O38*'AP01'!$P38)*'AP01'!$S38 -> 41.545728 | U38: ='AP01'!$Q38*0.00899% -> 38.8368
A39: =A38+1 -> 25 | B39: =EDATE(B38,1) -> 44003 | C39: 0.062 | D39: =D38 -> 0.005025 | E39: ='AP01'!$F39+'AP01'!$G39 -> 2258.25 | F39: 1418.25 | G39: =(O38*'AP01'!$P39)/($I$5-A38) -> 840 | H39: 39.47 | I39: 38.83 | J39: =J38 -> 25 | K39: =K38 -> 0 | L39: =L38 -> 0 | M39: =SUM('AP01'!$F39:$L39) -> 2361.55 | N39: =O38*('AP01'!$P39-1) -> 0 | O39: =(O38*'AP01'!$P39)-'AP01'!$G39 -> 281400 | P39: =P38 -> 1 | Q39: =(Q38*'AP01'!$P39) -> 432000 | R39: =DATEDIF($S$7,'AP01'!$B39,"Y") -> 34 | S39: =VLOOKUP('AP01'!$R39,SEGUROS!$A:$B,2,TRUE) -> 0.0001472 | T39: =('AP01'!$O39*'AP01'!$P39)*'AP01'!$S39 -> 41.42208 | U39: ='AP01'!$Q39*0.00899% -> 38.8368
A40: =A39+1 -> 26 | B40: =EDATE(B39,1) -> 44033 | C40: 0.062 | D40: =D39 -> 0.005025 | E40: ='AP01'!$F40+'AP01'!$G40 -> 2254.03 | F40: 1414.03 | G40: =(O39*'AP01'!$P40)/($I$5-A39) -> 840 | H40: 39.35 | I40: 38.83 | J40: =J39 -> 25 | K40: =K39 -> 0 | L40: =L39 -> 0 | M40: =SUM('AP01'!$F40:$L40) -> 2357.21 | N40: =O39*('AP01'!$P40-1) -> 0 | O40: =(O39*'AP01'!$P40)-'AP01'!$G40 -> 280560 | P40: =P39 -> 1 | Q40: =(Q39*'AP01'!$P40) -> 432000 | R40: =DATEDIF($S$7,'AP01'!$B40,"Y") -> 34 | S40: =VLOOKUP('AP01'!$R40,SEGUROS!$A:$B,2,TRUE) -> 0.0001472 | T40: =('AP01'!$O40*'AP01'!$P40)*'AP01'!$S40 -> 41.298432 | U40: ='AP01'!$Q40*0.00899% -> 38.8368
A41: =A40+1 -> 27 | B41: =EDATE(B40,1) -> 44064 | C41: 0.062 | D41: =D40 -> 0.005025 | E41: ='AP01'!$F41+'AP01'!$G41 -> 2249.81 | F41: 1409.81 | G41: =(O40*'AP01'!$P41)/($I$5-A40) -> 840 | H41: 39.24 | I41: 38.83 | J41: =J40 -> 25 | K41: =K40 -> 0 | L41: =L40 -> 0 | M41: =SUM('AP01'!$F41:$L41) -> 2352.88 | N41: =O40*('AP01'!$P41-1) -> 0 | O41: =(O40*'AP01'!$P41)-'AP01'!$G41 -> 279720 | P41: =P40 -> 1 | Q41: =(Q40*'AP01'!$P41) -> 432000 | R41: =DATEDIF($S$7,'AP01'!$B41,"Y") -> 34 | S41: =VLOOKUP('AP01'!$R41,SEGUROS!$A:$B,2,TRUE) -> 0.0001472 | T41: =('AP01'!$O41*'AP01'!$P41)*'AP01'!$S41 -> 41.174784 | U41: ='AP01'!$Q41*0.00899% -> 38.8368
...

Sheet SEGUROS
A1: Idade | B1: Taxa DFI
A2: 21 | B2: 7.57e-05
A3: =A2+1 -> 22 | B3: 7.57e-05
A4: =A3+1 -> 23 | B4: 7.57e-05
A5: =A4+1 -> 24 | B5: 7.57e-05
A6: =A5+1 -> 25 | B6: 7.57e-05
A7: =A6+1 -> 26 | B7: 7.57e-05
A8: =A7+1 -> 27 | B8: 7.57e-05
A9: =A8+1 -> 28 | B9: 7.57e-05
A10: =A9+1 -> 29 | B10: 7.57e-05
A11: =A10+1 -> 30 | B11: 7.57e-05
A12: 31 | B12: 0.000134
A13: =A12+1 -> 32 | B13: 0.0001381
A14: =A13+1 -> 33 | B14: 0.0001423
A15: =A14+1 -> 34 | B15: 0.0001472
A16: =A15+1 -> 35 | B16: 0.0001548
A17: =A16+1 -> 36 | B17: 0.0002337
A18: =A17+1 -> 37 | B18: 0.0002469
A19: =A18+1 -> 38 | B19: 0.0002632
A20: =A19+1 -> 39 | B20: 0.0002832
A21: =A20+1 -> 40 | B21: 0.0003073
A22: =A21+1 -> 41 | B22: 0.0003179
A23: =A22+1 -> 42 | B23: 0.0003181
A24: =A23+1 -> 43 | B24: 0.0003525
... A61: =A60+1 -> 80 | B61: 0.0155781

Sheet TR
A1: Data | B1: Data fim | C1: 226 - Taxa referencial (TR) - % a.m.
A2: 43221 | B2: 43251 | C2: 0
A3: 43221 | B3: 43252 | C3: 0
A4: 43222 | B4: 43253 | C4: 0
A5: 43223 | B5: 43254 | C5: 0
A6: 43224 | B6: 43255 | C6: 0
A7: 43225 | B7: 43256 | C7: 0
A8: 43226 | B8: 43257 | C8: 0
A9: 43227 | B9: 43258 | C9: 0
A10: 43228 | B10: 43259 | C10: 0
A11: 43229 | B11: 43260 | C11: 0
A12: 43230 | B12: 43261 | C12: 0
A13: 43231 | B13: 43262 | C13: 0
... A2643: 45814 | B2643: 45844 | C2643: 0.17
A2644: Fonte | B2644: - | C2644: BCB-Demab

Sheet AP02
A1: APÊNDICE 02: EVOLUÇÃO DO FINANCIAMENTO COM TAXA MÉDIA E EXPURGO DOS SEGUROS
A3: ='AP01'!A3 -> Requerente: ADRIANA MELO DE OLIVEIRA
A4: ='AP01'!A4 -> Requerido: ITAÚ UNIBANCO
A5: Valor do Bem | D5: ='AP01'!D5 -> 432000 | F5: Qtde Prestações | I5: ='AP01'!I5 -> 360 | L5: Para calcular a prestação (a+j):
A6: Entrada/Descontos | D6: ='AP01'!D6 -> 129600 | F6: Taxa MÉDIA Efetiva (a.m.) | I6: 0.0062 | L6: 1. Calcule a amortização dividindo o valor financiado pela quantidade de prestações; | T6: OBS: muda quando começa o vencimento com a correção monetária. Neste caso basta atualizar primeiro o saldo utilizando a mesma fórmula.
A7: Valor Financiado | D7: =D5-D6 -> 302400 | F7: Taxa MÉDIA Efetiva (a.a.) | I7: 0.0775 | L7: A = | M7: Valor Financiado | N7: =D7/I5 -> 840 | O7: <= cálculo feito
A8: Data do Contrato | D8: ='AP01'!D8 -> 43241 | F8: Taxa de Juros Efetiva (a.a.) | I8: ='AP01'!I7 -> 0.117 | M8: Qtde Pmt´s
A9: 1° Vencimento | D9: ='AP01'!D9 -> 43272 | F9: (%) Excesso Taxa Média | I9: =(I8/I7)-1 -> 0.50967742 | L9: 2. Depois é só calcular os juros aplicando sobre o saldo financiado o percentual da taxa;
A10: Sistema de Amortização | D10: ='AP01'!D10 -> SAC | F10: Prestação Mensal | I10: ='AP01'!I10 -> 2549.8136 | L10: J = | M10: Saldo Devedor x i% | N10: =D7*I6 -> 1874.88 | O10: <= cálculo feito
A11: Índice Correção | D11: ='AP01'!D11 -> TR | F11: Enquadramento | I11: ='AP01'!I11 -> SFH | L11: Pmt = A + J | N11: =N7+N10 -> 2714.88
A13: Qtde | B13: Data Vencimento | C13: Taxa Efetiva a.a. | D13: Taxa Efetiva a.m. | E13: Prestação (a+j) | F13: Juros | G13: Amortização | H13: Seguro MIP | I13: Seguro DFI | J13: TCA | K13: Multa | L13: Mora | M13: Total da Parcela Devida | N13: Correção Monetária | O13: Saldo Devedor | P13: Índice Correção
A14: 0 | B14: =D8 -> 43241 | O14: =D7 -> 302400
A15: =A14+1 -> 1 | B15: =D9 -> 43272 | C15: 0.07 | D15: 0.005654 | E15: ='AP02'!$F15+'AP02'!$G15 -> 2549.7696 | F15: =(O14*'AP02'!$P15)*'AP02'!$D15 -> 1709.7696 | G15: =(O14*'AP02'!$P15)/($I$5-A14) -> 840 | H15: 0 | I15: 0 | J15: 25 | K15: 0 | L15: 0 | M15: =SUM('AP02'!$F15:$L15) -> 2574.7696 | N15: =O14*('AP02'!$P15-1) -> 0 | O15: =(O14*'AP02'!$P15)-'AP02'!$G15 -> 301560 | P15: 1
A16: =A15+1 -> 2 | B16: =EDATE(B15,1) -> 43302 | C16: =C15 -> 0.07 | D16: =D15 -> 0.005654 | E16: ='AP02'!$F16+'AP02'!$G16 -> 2545.0202 | F16: =(O15*'AP02'!$P16)*'AP02'!$D16 -> 1705.0202 | G16: =(O15*'AP02'!$P16)/($I$5-A15) -> 840 | H16: =H15 -> 0 | I16: =I15 -> 0 | J16: =J15 -> 25 | K16: =K15 -> 0 | L16: =L15 -> 0 | M16: =SUM('AP02'!$F16:$L16) -> 2570.0202 | N16: =O15*('AP02'!$P16-1) -> 0 | O16: =(O15*'AP02'!$P16)-'AP02'!$G16 -> 300720 | P16: =P15 -> 1
A17: =A16+1 -> 3 | B17: =EDATE(B16,1) -> 43333 | C17: =C16 -> 0.07 | D17: =D16 -> 0.005654 | E17: ='AP02'!$F17+'AP02'!$G17 -> 2540.2709 | F17: =(O16*'AP02'!$P17)*'AP02'!$D17 -> 1700.2709 | G17: =(O16*'AP02'!$P17)/($I$5-A16) -> 840 | H17: =H16 -> 0 | I17: =I16 -> 0 | J17: =J16 -> 25 | K17: =K16 -> 0 | L17: =L16 -> 0 | M17: =SUM('AP02'!$F17:$L17) -> 2565.2709 | N17: =O16*('AP02'!$P17-1) -> 0 | O17: =(O16*'AP02'!$P17)-'AP02'!$G17 -> 299880 | P17: =P16 -> 1
A18: =A17+1 -> 4 | B18: =EDATE(B17,1) -> 43364 | C18: =C17 -> 0.07 | D18: =D17 -> 0.005654 | E18: ='AP02'!$F18+'AP02'!$G18 -> 2535.5215 | F18: =(O17*'AP02'!$P18)*'AP02'!$D18 -> 1695.5215 | G18: =(O17*'AP02'!$P18)/($I$5-A17) -> 840 | H18: =H17 -> 0 | I18: =I17 -> 0 | J18: =J17 -> 25 | K18: =K17 -> 0 | L18: =L17 -> 0 | M18: =SUM('AP02'!$F18:$L18) -> 2560.5215 | N18: =O17*('AP02'!$P18-1) -> 0 | O18: =(O17*'AP02'!$P18)-'AP02'!$G18 -> 299040 | P18: =P17 -> 1
A19: =A18+1 -> 5 | B19: =EDATE(B18,1) -> 43394 | C19: =C18 -> 0.07 | D19: =D18 -> 0.005654 | E19: ='AP02'!$F19+'AP02'!$G19 -> 2530.7722 | F19: =(O18*'AP02'!$P19)*'AP02'!$D19 -> 1690.7722 | G19: =(O18*'AP02'!$P19)/($I$5-A18) -> 840 | H19: =H18 -> 0 | I19: =I18 -> 0 | J19: =J18 -> 25 | K19: =K18 -> 0 | L19: =L18 -> 0 | M19: =SUM('AP02'!$F19:$L19) -> 2555.7722 | N19: =O18*('AP02'!$P19-1) -> 0 | O19: =(O18*'AP02'!$P19)-'AP02'!$G19 -> 298200 | P19: =P18 -> 1
A20: =A19+1 -> 6 | B20: =EDATE(B19,1) -> 43425 | C20: =C19 -> 0.07 | D20: =D19 -> 0.005654 | E20: ='AP02'!$F20+'AP02'!$G20 -> 2526.0228 | F20: =(O19*'AP02'!$P20)*'AP02'!$D20 -> 1686.0228 | G20: =(O19*'AP02'!$P20)/($I$5-A19) -> 840 | H20: =H19 -> 0 | I20: =I19 -> 0 | J20: =J19 -> 25 | K20: =K19 -> 0 | L20: =L19 -> 0 | M20: =SUM('AP02'!$F20:$L20) -> 2551.0228 | N20: =O19*('AP02'!$P20-1) -> 0 | O20: =(O19*'AP02'!$P20)-'AP02'!$G20 -> 297360 | P20: =P19 -> 1
A21: =A20+1 -> 7 | B21: =EDATE(B20,1) -> 43455 | C21: =C20 -> 0.07 | D21: =D20 -> 0.005654 | E21: ='AP02'!$F21+'AP02'!$G21 -> 2521.2734 | F21: =(O20*'AP02'!$P21)*'AP02'!$D21 -> 1681.2734 | G21: =(O20*'AP02'!$P21)/($I$5-A20) -> 840 | H21: =H20 -> 0 | I21: =I20 -> 0 | J21: =J20 -> 25 | K21: =K20 -> 0 | L21: =L20 -> 0 | M21: =SUM('AP02'!$F21:$L21) -> 2546.2734 | N21: =O20*('AP02'!$P21-1) -> 0 | O21: =(O20*'AP02'!$P21)-'AP02'!$G21 -> 296520 | P21: =P20 -> 1
A22: =A21+1 -> 8 | B22: =EDATE(B21,1) -> 43486 | C22: =C21 -> 0.07 | D22: =D21 -> 0.005654 | E22: ='AP02'!$F22+'AP02'!$G22 -> 2516.5241 | F22: =(O21*'AP02'!$P22)*'AP02'!$D22 -> 1676.5241 | G22: =(O21*'AP02'!$P22)/($I$5-A21) -> 840 | H22: =H21 -> 0 | I22: =I21 -> 0 | J22: =J21 -> 25 | K22: =K21 -> 0 | L22: =L21 -> 0 | M22: =SUM('AP02'!$F22:$L22) -> 2541.5241 | N22: =O21*('AP02'!$P22-1) -> 0 | O22: =(O21*'AP02'!$P22)-'AP02'!$G22 -> 295680 | P22: =P21 -> 1
A23: =A22+1 -> 9 | B23: =EDATE(B22,1) -> 43517 | C23: =C22 -> 0.07 | D23: =D22 -> 0.005654 | E23: ='AP02'!$F23+'AP02'!$G23 -> 2511.7747 | F23: =(O22*'AP02'!$P23)*'AP02'!$D23 -> 1671.7747 | G23: =(O22*'AP02'!$P23)/($I$5-A22) -> 840 | H23: =H22 -> 0 | I23: =I22 -> 0 | J23: =J22 -> 25 | K23: =K22 -> 0 | L23: =L22 -> 0 | M23: =SUM('AP02'!$F23:$L23) -> 2536.7747 | N23: =O22*('AP02'!$P23-1) -> 0 | O23: =(O22*'AP02'!$P23)-'AP02'!$G23 -> 294840 | P23: =P22 -> 1
A24: =A23+1 -> 10 | B24: =EDATE(B23,1) -> 43545 | C24: =C23 -> 0.07 | D24: =D23 -> 0.005654 | E24: ='AP02'!$F24+'AP02'!$G24 -> 2507.0254 | F24: =(O23*'AP02'!$P24)*'AP02'!$D24 -> 1667.0254 | G24: =(O23*'AP02'!$P24)/($I$5-A23) -> 840 | H24: =H23 -> 0 | I24: =I23 -> 0 | J24: =J23 -> 25 | K24: =K23 -> 0 | L24: =L23 -> 0 | M24: =SUM('AP02'!$F24:$L24) -> 2532.0254 | N24: =O23*('AP02'!$P24-1) -> 0 | O24: =(O23*'AP02'!$P24)-'AP02'!$G24 -> 294000 | P24: =P23 -> 1
A25: =A24+1 -> 11 | B25: =EDATE(B24,1) -> 43576 | C25: =C24 -> 0.07 | D25: =D24 -> 0.005654 | E25: ='AP02'!$F25+'AP02'!$G25 -> 2502.276 | F25: =(O24*'AP02'!$P25)*'AP02'!$D25 -> 1662.276 | G25: =(O24*'AP02'!$P25)/($I$5-A24) -> 840 | H25: =H24 -> 0 | I25: =I24 -> 0 | J25: =J24 -> 25 | K25: =K24 -> 0 | L25: =L24 -> 0 | M25: =SUM('AP02'!$F25:$L25) -> 2527.276 | N25: =O24*('AP02'!$P25-1) -> 0 | O25: =(O24*'AP02'!$P25)-'AP02'!$G25 -> 293160 | P25: =P24 -> 1
A26: =A25+1 -> 12 | B26: =EDATE(B25,1) -> 43606 | C26: =C25 -> 0.07 | D26: =D25 -> 0.005654 | E26: ='AP02'!$F26+'AP02'!$G26 -> 2497.5266 | F26: =(O25*'AP02'!$P26)*'AP02'!$D26 -> 1657.5266 | G26: =(O25*'AP02'!$P26)/($I$5-A25) -> 840 | H26: =H25 -> 0 | I26: =I25 -> 0 | J26: =J25 -> 25 | K26: =K25 -> 0 | L26: =L25 -> 0 | M26: =SUM('AP02'!$F26:$L26) -> 2522.5266 | N26: =O25*('AP02'!$P26-1) -> 0 | O26: =(O25*'AP02'!$P26)-'AP02'!$G26 -> 292320 | P26: =P25 -> 1
A27: =A26+1 -> 13 | B27: =EDATE(B26,1) -> 43637 | C27: =C26 -> 0.07 | D27: =D26 -> 0.005654 | E27: ='AP02'!$F27+'AP02'!$G27 -> 2492.7773 | F27: =(O26*'AP02'!$P27)*'AP02'!$D27 -> 1652.7773 | G27: =(O26*'AP02'!$P27)/($I$5-A26) -> 840 | H27: =H26 -> 0 | I27: =I26 -> 0 | J27: =J26 -> 25 | K27: =K26 -> 0 | L27: =L26 -> 0 | M27: =SUM('AP02'!$F27:$L27) -> 2517.7773 | N27: =O26*('AP02'!$P27-1) -> 0 | O27: =(O26*'AP02'!$P27)-'AP02'!$G27 -> 291480 | P27: =P26 -> 1
... A35: =A34+1 -> 21 | B35: =EDATE(B34,1) -> 43882 | C35: =C34 -> 0.07 | D35: =D34 -> 0.005654 | E35: ='AP02'!$F35+'AP02'!$G35 -> 2454.7824 | F35: =(O34*'AP02'!$P35)*'AP02'!$D35 -> 1614.7824 | G35: =(O34*'AP02'!$P35)/($I$5-A34) -> 840 | H35: =H34 -> 0 | I35: =I34 -> 0 | J35: =J34 -> 25 | K35: =K34 -> 0 | L35: =L34 -> 0 | M35: =SUM('AP02'!$F35:$L35) -> 2479.7824 | N35: =O34*('AP02'!$P35-1) -> 0 | O35: =(O34*'AP02'!$P35)-'AP02'!$G35 -> 284760 | P35: =P34 -> 1
A36: =A35+1 -> 22 | B36: =EDATE(B35,1) -> 43911 | C36: 0.062 | D36: 0.005025 | E36: ='AP02'!$F36+'AP02'!$G36 -> 2270.919 | F36: =(O35*'AP02'!$P36)*'AP02'!$D36 -> 1430.919 | G36: =(O35*'AP02'!$P36)/($I$5-A35) -> 840 | H36: =H35 -> 0 | I36: =I35 -> 0 | J36: =J35 -> 25 | K36: =K35 -> 0 | L36: =L35 -> 0 | M36: =SUM('AP02'!$F36:$L36) -> 2295.919 | N36: =O35*('AP02'!$P36-1) -> 0 | O36: =(O35*'AP02'!$P36)-'AP02'!$G36 -> 283920 | P36: =P35 -> 1
A37: =A36+1 -> 23 | B37: =EDATE(B36,1) -> 43942 | C37: 0.062 | D37: =D36 -> 0.005025 | E37: ='AP02'!$F37+'AP02'!$G37 -> 2266.698 | F37: =(O36*'AP02'!$P37)*'AP02'!$D37 -> 1426.698 | G37: =(O36*'AP02'!$P37)/($I$5-A36) -> 840 | H37: =H36 -> 0 | I37: =I36 -> 0 | J37: =J36 -> 25 | K37: =K36 -> 0 | L37: =L36 -> 0 | M37: =SUM('AP02'!$F37:$L37) -> 2291.698 | N37: =O36*('AP02'!$P37-1) -> 0 | O37: =(O36*'AP02'!$P37)-'AP02'!$G37 -> 283080 | P37: =P36 -> 1
A38: =A37+1 -> 24 | B38: =EDATE(B37,1) -> 43972 | C38: 0.062 | D38: =D37 -> 0.005025 | E38: ='AP02'!$F38+'AP02'!$G38 -> 2262.477 | F38: =(O37*'AP02'!$P38)*'AP02'!$D38 -> 1422.477 | G38: =(O37*'AP02'!$P38)/($I$5-A37) -> 840 | H38: =H37 -> 0 | I38: =I37 -> 0 | J38: =J37 -> 25 | K38: =K37 -> 0 | L38: =L37 -> 0 | M38: =SUM('AP02'!$F38:$L38) -> 2287.477 | N38: =O37*('AP02'!$P38-1) -> 0 | O38: =(O37*'AP02'!$P38)-'AP02'!$G38 -> 282240 | P38: =P37 -> 1
A39: =A38+1 -> 25 | B39: =EDATE(B38,1) -> 44003 | C39: 0.062 | D39: =D38 -> 0.005025 | E39: ='AP02'!$F39+'AP02'!$G39 -> 2258.256 | F39: =(O38*'AP02'!$P39)*'AP02'!$D39 -> 1418.256 | G39: =(O38*'AP02'!$P39)/($I$5-A38) -> 840 | H39: =H38 -> 0 | I39: =I38 -> 0 | J39: =J38 -> 25 | K39: =K38 -> 0 | L39: =L38 -> 0 | M39: =SUM('AP02'!$F39:$L39) -> 2283.256 | N39: =O38*('AP02'!$P39-1) -> 0 | O39: =(O38*'AP02'!$P39)-'AP02'!$G39 -> 281400 | P39: =P38 -> 1
A40: =A39+1 -> 26 | B40: =EDATE(B39,1) -> 44033 | C40: 0.062 | D40: =D39 -> 0.005025 | E40: ='AP02'!$F40+'AP02'!$G40 -> 2254.035 | F40: =(O39*'AP02'!$P40)*'AP02'!$D40 -> 1414.035 | G40: =(O39*'AP02'!$P40)/($I$5-A39) -> 840 | H40: =H39 -> 0 | I40: =I39 -> 0 | J40: =J39 -> 25 | K40: =K39 -> 0 | L40: =L39 -> 0 | M40: =SUM('AP02'!$F40:$L40) -> 2279.035 | N40: =O39*('AP02'!$P40-1) -> 0 | O40: =(O39*'AP02'!$P40)-'AP02'!$G40 -> 280560 | P40: =P39 -> 1
A41: =A40+1 -> 27 | B41: =EDATE(B40,1) -> 44064 | C41: 0.062 | D41: =D40 -> 0.005025 | E41: ='AP02'!$F41+'AP02'!$G41 -> 2249.814 | F41: =(O40*'AP02'!$P41)*'AP02'!$D41 -> 1409.814 | G41: =(O40*'AP02'!$P41)/($I$5-A40) -> 840 | H41: =H40 -> 0 | I41: =I40 -> 0 | J41: =J40 -> 25 | K41: =K40 -> 0 | L41: =L40 -> 0 | M41: =SUM('AP02'!$F41:$L41) -> 2274.814 | N41: =O40*('AP02'!$P41-1) -> 0 | O41: =(O40*'AP02'!$P41)-'AP02'!$G41 -> 279720 | P41: =P40 -> 1
A42: =A41+1 -> 28 | B42: =EDATE(B41,1) -> 44095 | C42: =C41 -> 0.062 | D42: =D41 -> 0.005025 | E42: ='AP02'!$F42+'AP02'!$G42 -> 2245.593 | F42: =(O41*'AP02'!$P42)*'AP02'!$D42 -> 1405.593 | G42: =(O41*'AP02'!$P42)/($I$5-A41) -> 840 | H42: =H41 -> 0 | I42: =I41 -> 0 | J42: =J41 -> 25 | K42: =K41 -> 0 | L42: =L41 -> 0 | M42: =SUM('AP02'!$F42:$L42) -> 2270.593 | N42: =O41*('AP02'!$P42-1) -> 0 | O42: =(O41*'AP02'!$P42)-'AP02'!$G42 -> 278880 | P42: =P41 -> 1
A43: =A42+1 -> 29 | B43: =EDATE(B42,1) -> 44125 | C43: =C42 -> 0.062 | D43: =D42 -> 0.005025 | E43: ='AP02'!$F43+'AP02'!$G43 -> 2241.372 | F43: =(O42*'AP02'!$P43)*'AP02'!$D43 -> 1401.372 | G43: =(O42*'AP02'!$P43)/($I$5-A42) -> 840 | H43: =H42 -> 0 | I43: =I42 -> 0 | J43: =J42 -> 25 | K43: =K42 -> 0 | L43: =L42 -> 0 | M43: =SUM('AP02'!$F43:$L43) -> 2266.372 | N43: =O42*('AP02'!$P43-1) -> 0 | O43: =(O42*'AP02'!$P43)-'AP02'!$G43 -> 278040 | P43: =P42 -> 1
A44: =A43+1 -> 30 | B44: =EDATE(B43,1) -> 44156 | C44: =C43 -> 0.062 | D44: =D43 -> 0.005025 | E44: ='AP02'!$F44+'AP02'!$G44 -> 2237.151 | F44: =(O43*'AP02'!$P44)*'AP02'!$D44 -> 1397.151 | G44: =(O43*'AP02'!$P44)/($I$5-A43) -> 840 | H44: =H43 -> 0 | I44: =I43 -> 0 | J44: =J43 -> 25 | K44: =K43 -> 0 | L44: =L43 -> 0 | M44: =SUM('AP02'!$F44:$L44) -> 2262.151 | N44: =O43*('AP02'!$P44-1) -> 0 | O44: =(O43*'AP02'!$P44)-'AP02'!$G44 -> 277200 | P44: =P43 -> 1
A45: =A44+1 -> 31 | B45: =EDATE(B44,1) -> 44186 | C45: =C44 -> 0.062 | D45: =D44 -> 0.005025 | E45: ='AP02'!$F45+'AP02'!$G45 -> 2232.93 | F45: =(O44*'AP02'!$P45)*'AP02'!$D45 -> 1392.93 | G45: =(O44*'AP02'!$P45)/($I$5-A44) -> 840 | H45: =H44 -> 0 | I45: =I44 -> 0 | J45: =J44 -> 25 | K45: =K44 -> 0 | L45: =L44 -> 0 | M45: =SUM('AP02'!$F45:$L45) -> 2257.93 | N45: =O44*('AP02'!$P45-1) -> 0 | O45: =(O44*'AP02'!$P45)-'AP02'!$G45 -> 276360 | P45: =P44 -> 1
A46: =A45+1 -> 32 | B46: =EDATE(B45,1) -> 44217 | C46: =C45 -> 0.062 | D46: =D45 -> 0.005025 | E46: ='AP02'!$F46+'AP02'!$G46 -> 2228.709 | F46: =(O45*'AP02'!$P46)*'AP02'!$D46 -> 1388.709 | G46: =(O45*'AP02'!$P46)/($I$5-A45) -> 840 | H46: =H45 -> 0 | I46: =I45 -> 0 | J46: =J45 -> 25 | K46: =K45 -> 0 | L46: =L45 -> 0 | M46: =SUM('AP02'!$F46:$L46) -> 2253.709 | N46: =O45*('AP02'!$P46-1) -> 0 | O46: =(O45*'AP02'!$P46)-'AP02'!$G46 -> 275520 | P46: =P45 -> 1
A47: =A46+1 -> 33 | B47: =EDATE(B46,1) -> 44248 | C47: =C46 -> 0.062 | D47: =D46 -> 0.005025 | E47: ='AP02'!$F47+'AP02'!$G47 -> 2224.488 | F47: =(O46*'AP02'!$P47)*'AP02'!$D47 -> 1384.488 | G47: =(O46*'AP02'!$P47)/($I$5-A46) -> 840 | H47: =H46 -> 0 | I47: =I46 -> 0 | J47: =J46 -> 25 | K47: =K46 -> 0 | L47: =L46 -> 0 | M47: =SUM('AP02'!$F47:$L47) -> 2249.488 | N47: =O46*('AP02'!$P47-1) -> 0 | O47: =(O46*'AP02'!$P47)-'AP02'!$G47 -> 274680 | P47: =P46 -> 1
A48: =A47+1 -> 34 | B48: =EDATE(B47,1) -> 44276 | C48: =C47 -> 0.062 | D48: =D47 -> 0.005025 | E48: ='AP02'!$F48+'AP02'!$G48 -> 2220.267 | F48: =(O47*'AP02'!$P48)*'AP02'!$D48 -> 1380.267 | G48: =(O47*'AP02'!$P48)/($I$5-A47) -> 840 | H48: =H47 -> 0 | I48: =I47 -> 0 | J48: =J47 -> 25 | K48: =K47 -> 0 | L48: =L47 -> 0 | M48: =SUM('AP02'!$F48:$L48) -> 2245.267 | N48: =O47*('AP02'!$P48-1) -> 0 | O48: =(O47*'AP02'!$P48)-'AP02'!$G48 -> 273840 | P48: =P47 -> 1
A49: =A48+1 -> 35 | B49: =EDATE(B48,1) -> 44307 | C49: =C48 -> 0.062 | D49: =D48 -> 0.005025 | E49: ='AP02'!$F49+'AP02'!$G49 -> 2216.046 | F49: =(O48*'AP02'!$P49)*'AP02'!$D49 -> 1376.046 | G49: =(O48*'AP02'!$P49)/($I$5-A48) -> 840 | H49: =H48 -> 0 | I49: =I48 -> 0 | J49: =J48 -> 25 | K49: =K48 -> 0 | L49: =L48 -> 0 | M49: =SUM('AP02'!$F49:$L49) -> 2241.046 | N49: =O48*('AP02'!$P49-1) -> 0 | O49: =(O48*'AP02'!$P49)-'AP02'!$G49 -> 273000 | P49: =P48 -> 1
...

Sheet AP03
A1: APÊNDICE 03: DEMONSTRATIVO DAS DIFERENÇAS EXCEDENTES A RESTITUIR
A3: ='AP01'!A3 -> Requerente: ADRIANA MELO DE OLIVEIRA
A4: ='AP01'!A4 -> Requerido: ITAÚ UNIBANCO
A6: Qtde | B6: Data Vencimento | C6: Situação da Parcela | D6: Valor Pago / Prestação Cobrada | E6: Valor Devido / Prestação Devida | F6: Diferença Mensal | G6: TOTAL NOMINAL A RESTITUIR
A7: 0 | B7: ='AP01'!B14 -> 43241 | G7: 0
A8: =A7+1 -> 1 | B8: ='AP01'!B15 -> 43272 | C8: Paga | D8: 2714.96 | E8: ='AP02'!M15 -> 2574.7696 | F8: =D8-E8 -> 140.1904 | G8: =G7+'AP03'!$F8 -> 140.1904
A9: =A8+1 -> 2 | B9: ='AP01'!B16 -> 43302 | C9: Paga | D9: 2640.04 | E9: ='AP02'!M16 -> 2570.0202 | F9: =F8 -> 140.1904 | G9: =G8+'AP03'!$F9 -> 280.3808
A10: =A9+1 -> 3 | B10: ='AP01'!B17 -> 43333 | C10: Paga | D10: 2635.2 | E10: ='AP02'!M17 -> 2565.2709 | F10: =D10-E10 -> 69.92912 | G10: =G9+'AP03'!$F10 -> 350.30992
A11: =A10+1 -> 4 | B11: ='AP01'!B18 -> 43364 | C11: Paga | D11: 2630.36 | E11: ='AP02'!M18 -> 2560.5215 | F11: =D11-E11 -> 69.83848 | G11: =G10+'AP03'!$F11 -> 420.1484
A12: =A11+1 -> 5 | B12: ='AP01'!B19 -> 43394 | C12: Paga | D12: 2625.52 | E12: ='AP02'!M19 -> 2555.7722 | F12: =D12-E12 -> 69.74784 | G12: =G11+'AP03'!$F12 -> 489.89624
A13: =A12+1 -> 6 | B13: ='AP01'!B20 -> 43425 | C13: Paga | D13: 2620.69 | E13: ='AP02'!M20 -> 2551.0228 | F13: =D13-E13 -> 69.6672 | G13: =G12+'AP03'!$F13 -> 559.56344
A14: =A13+1 -> 7 | B14: ='AP01'!B21 -> 43455 | C14: Paga | D14: 2616.41 | E14: ='AP02'!M21 -> 2546.2734 | F14: =D14-E14 -> 70.13656 | G14: =G13+'AP03'!$F14 -> 629.7
A15: =A14+1 -> 8 | B15: ='AP01'!B22 -> 43486 | C15: Paga | D15: 2611.57 | E15: ='AP02'!M22 -> 2541.5241 | F15: =D15-E15 -> 70.04592 | G15: =G14+'AP03'!$F15 -> 699.74592
A16: =A15+1 -> 9 | B16: ='AP01'!B23 -> 43517 | C16: Paga | D16: 2606.73 | E16: ='AP02'!M23 -> 2536.7747 | F16: =D16-E16 -> 69.95528 | G16: =G15+'AP03'!$F16 -> 769.7012
A17: =A16+1 -> 10 | B17: ='AP01'!B24 -> 43545 | C17: Paga | D17: 2601.89 | E17: ='AP02'!M24 -> 2532.0254 | F17: =D17-E17 -> 69.86464 | G17: =G16+'AP03'!$F17 -> 839.56584
A18: =A17+1 -> 11 | B18: ='AP01'!B25 -> 43576 | C18: Paga | D18: 2597.05 | E18: ='AP02'!M25 -> 2527.276 | F18: =D18-E18 -> 69.774 | G18: =G17+'AP03'!$F18 -> 909.33984
A19: =A18+1 -> 12 | B19: ='AP01'!B26 -> 43606 | C19: Paga | D19: 2592.21 | E19: ='AP02'!M26 -> 2522.5266 | F19: =D19-E19 -> 69.68336 | G19: =G18+'AP03'!$F19 -> 979.0232
A20: =A19+1 -> 13 | B20: ='AP01'!B27 -> 43637 | C20: Paga | D20: 2587.38 | E20: ='AP02'!M27 -> 2517.7773 | F20: =D20-E20 -> 69.60272 | G20: =G19+'AP03'!$F20 -> 1048.6259
A21: =A20+1 -> 14 | B21: ='AP01'!B28 -> 43667 | C21: Paga | D21: 2582.54 | E21: ='AP02'!M28 -> 2513.0279 | F21: =D21-E21 -> 69.51208 | G21: =G20+'AP03'!$F21 -> 1118.138
... A90: =A89+1 -> 83 | B90: ='AP01'!B97 -> 45768 | C90: Paga | D90: 3127.79 | E90: ='AP02'!M97 -> 2481.349 | F90: =D90-E90 -> 646.441 | G90: =G89+'AP03'!$F90 -> 23584.045
A91: =A90+1 -> 84 | B91: ='AP01'!B98 -> 45798 | D91: ='AP01'!M98 -> 3120.0187 | E91: ='AP02'!M98 -> 2475.7443 | F91: =D91-E91 -> 644.27437 | G91: =G90+'AP03'!$F91 -> 24228.319
A92: =A91+1 -> 85 | B92: ='AP01'!B99 -> 45829 | D92: ='AP01'!M99 -> 3112.2516 | E92: ='AP02'!M99 -> 2470.1396 | F92: =D92-E92 -> 642.11201 | G92: =G91+'AP03'!$F92 -> 24870.431
A93: =A92+1 -> 86 | B93: ='AP01'!B100 -> 45859 | D93: ='AP01'!M100 -> 3104.4845 | E93: ='AP02'!M100 -> 2464.5349 | F93: =D93-E93 -> 639.94966 | G93: =G92+'AP03'!$F93 -> 25510.381
A94: =A93+1 -> 87 | B94: ='AP01'!B101 -> 45890 | D94: ='AP01'!M101 -> 3096.7174 | E94: ='AP02'!M101 -> 2458.9301 | F94: =D94-E94 -> 637.7873 | G94: =G93+'AP03'!$F94 -> 26148.168
A95: =A94+1 -> 88 | B95: ='AP01'!B102 -> 45921 | D95: ='AP01'!M102 -> 3088.9504 | E95: ='AP02'!M102 -> 2453.3254 | F95: =D95-E95 -> 635.62494 | G95: =G94+'AP03'!$F95 -> 26783.793
A96: =A95+1 -> 89 | B96: ='AP01'!B103 -> 45951 | D96: ='AP01'!M103 -> 3081.1833 | E96: ='AP02'!M103 -> 2447.7207 | F96: =D96-E96 -> 633.46258 | G96: =G95+'AP03'!$F96 -> 27417.256
A97: =A96+1 -> 90 | B97: ='AP01'!B104 -> 45982 | D97: ='AP01'!M104 -> 3073.4162 | E97: ='AP02'!M104 -> 2442.116 | F97: =D97-E97 -> 631.30022 | G97: =G96+'AP03'!$F97 -> 28048.556
A98: =A97+1 -> 91 | B98: ='AP01'!B105 -> 46012 | D98: ='AP01'!M105 -> 3078.2227 | E98: ='AP02'!M105 -> 2436.5113 | F98: =D98-E98 -> 641.71143 | G98: =G97+'AP03'!$F98 -> 28690.267
A99: =A98+1 -> 92 | B99: ='AP01'!B106 -> 46043 | D99: ='AP01'!M106 -> 3070.409 | E99: ='AP02'!M106 -> 2430.9065 | F99: =D99-E99 -> 639.5025 | G99: =G98+'AP03'!$F99 -> 29329.77
A100: =A99+1 -> 93 | B100: ='AP01'!B107 -> 46074 | D100: ='AP01'!M107 -> 3062.5954 | E100: ='AP02'!M107 -> 2425.3018 | F100: =D100-E100 -> 637.29357 | G100: =G99+'AP03'!$F100 -> 29967.063
A101: =A100+1 -> 94 | B101: ='AP01'!B108 -> 46102 | D101: ='AP01'!M108 -> 3054.7818 | E101: ='AP02'!M108 -> 2419.6971 | F101: =D101-E101 -> 635.08464 | G101: =G100+'AP03'!$F101 -> 30602.148
A102: =A101+1 -> 95 | B102: ='AP01'!B109 -> 46133 | D102: ='AP01'!M109 -> 3046.9681 | E102: ='AP02'!M109 -> 2414.0924 | F102: =D102-E102 -> 632.87571 | G102: =G101+'AP03'!$F102 -> 31235.024
... A366: =A365+1 -> 359 | B366: ='AP01'!B373 -> 54169 | D366: ='AP01'!M373 -> 989.09681 | E366: ='AP02'!M373 -> 934.44711 | F366: =D366-E366 -> 54.649696 | G366: =G365+'AP03'!$F366 -> 132897.78
A367: =A366+1 -> 360 | B367: ='AP01'!B374 -> 54199 | D367: ='AP01'!M374 -> 978.8176 | E367: ='AP02'!M374 -> 928.8424 | F367: =D367-E367 -> 49.975206 | G367: =G366+'AP03'!$F367 -> 132947.75 | I367: ='AP03'!$G367/'AP01'!D7 -> 0.43964204
A369: Este apêndice retrata a diferença excessiva cobrada mensalmente, a serem restituídas em DOBRO e na forma SIMPLES, conforme retratados nos apêndices 04 e 05.

Sheet AP04
A1: APÊNDICE 04: EVOLUÇÃO DO FINANCIAMENTO COM TAXA MÉDIA E EXPURGO DOS SEGUROS => COM REST. EM DOBRO
A3: ='AP01'!A3 -> Requerente: ADRIANA MELO DE OLIVEIRA
A4: ='AP01'!A4 -> Requerido: ITAÚ UNIBANCO
A5: Valor do Bem | D5: ='AP01'!D5 -> 432000 | F5: Qtde Prestações | I5: ='AP01'!I5 -> 360
A6: Entrada/Descontos | D6: ='AP01'!D6 -> 129600 | F6: Taxa MÉDIA Efetiva (a.m.) | I6: 0.0062
A7: Valor Financiado | D7: =D5-D6 -> 302400 | F7: Taxa MÉDIA Efetiva (a.a.) | I7: 0.0775
A8: Data do Contrato | D8: ='AP01'!D8 -> 43241 | F8: Taxa de Juros Efetiva (a.a.) | I8: ='AP01'!I7 -> 0.117
A9: 1° Vencimento | D9: ='AP01'!D9 -> 43272 | F9: (%) Excesso Taxa Média | I9: =(I8/I7)-1 -> 0.50967742
A10: Sistema de Amortização | D10: ='AP01'!D10 -> SAC | F10: Prestação Mensal | I10: ='AP01'!I10 -> 2549.8136
A11: Índice Correção | D11: ='AP01'!D11 -> TR | F11: Enquadramento | I11: ='AP01'!I11 -> SFH
A13: Qtde | B13: Data Vencimento | C13: Taxa Efetiva a.a. | D13: Taxa Efetiva a.m. | E13: Prestação (a+j) | F13: Juros | G13: (1) Amortização | H13: Seguro MIP | I13: Seguro DFI | J13: TCA | K13: Multa | L13: Mora | M13: (2) Valor Pago | N13: (3) Total da Parcela Devida | O13: (4) Diferença a Compensar [2-3] | P13: Correção Monetária | Q13: (5) Saldo Devedor [(5*TR)-1-4*2] | R13: Índice Correção
A14: 0 | B14: =D8 -> 43241 | Q14: =D7 -> 302400
A15: =A14+1 -> 1 | B15: =D9 -> 43272 | C15: 0.07 | D15: 0.005654 | E15: ='AP04'!$F15+'AP04'!$G15 -> 2549.7696 | F15: =(Q14*'AP04'!$R15)*'AP04'!$D15 -> 1709.7696 | G15: =(Q14*'AP04'!$R15)/($I$5-A14) -> 840 | H15: 0 | I15: 0 | J15: 25 | K15: 0 | L15: 0 | M15: ='AP03'!D8 -> 2714.96 | N15: =SUM('AP04'!$F15:$L15) -> 2574.7696 | O15: ='AP04'!$M15-'AP04'!$N15 -> 140.1904 | P15: =Q14*('AP04'!$R15-1) -> 0 | Q15: =(Q14*'AP04'!$R15)-'AP04'!$G15-'AP04'!$O15*2 -> 301279.62 | R15: 1
A16: =A15+1 -> 2 | B16: =EDATE(B15,1) -> 43302 | C16: =C15 -> 0.07 | D16: =D15 -> 0.005654 | E16: ='AP04'!$F16+'AP04'!$G16 -> 2542.654 | F16: =(Q15*'AP04'!$R16)*'AP04'!$D16 -> 1703.435 | G16: =(Q15*'AP04'!$R16)/($I$5-A15) -> 839.21899 | H16: =H15 -> 0 | I16: =I15 -> 0 | J16: =J15 -> 25 | K16: =K15 -> 0 | L16: =L15 -> 0 | M16: ='AP03'!D9 -> 2640.04 | N16: =SUM('AP04'!$F16:$L16) -> 2567.654 | O16: ='AP04'!$M16-'AP04'!$N16 -> 72.386038 | P16: =Q15*('AP04'!$R16-1) -> 0 | Q16: =(Q15*'AP04'!$R16)-'AP04'!$G16-'AP04'!$O16*2 -> 300295.63 | R16: =R15 -> 1
A17: =A16+1 -> 3 | B17: =EDATE(B16,1) -> 43333 | C17: =C16 -> 0.07 | D17: =D16 -> 0.005654 | E17: ='AP04'!$F17+'AP04'!$G17 -> 2536.6861 | F17: =(Q16*'AP04'!$R17)*'AP04'!$D17 -> 1697.8715 | G17: =(Q16*'AP04'!$R17)/($I$5-A16) -> 838.8146 | H17: =H16 -> 0 | I17: =I16 -> 0 | J17: =J16 -> 25 | K17: =K16 -> 0 | L17: =L16 -> 0 | M17: ='AP03'!D10 -> 2635.2 | N17: =SUM('AP04'!$F17:$L17) -> 2561.6861 | O17: ='AP04'!$M17-'AP04'!$N17 -> 73.513915 | P17: =Q16*('AP04'!$R17-1) -> 0 | Q17: =(Q16*'AP04'!$R17)-'AP04'!$G17-'AP04'!$O17*2 -> 299309.79 | R17: =R16 -> 1
A18: =A17+1 -> 4 | B18: =EDATE(B17,1) -> 43364 | C18: =C17 -> 0.07 | D18: =D17 -> 0.005654 | E18: ='AP04'!$F18+'AP04'!$G18 -> 2530.7003 | F18: =(Q17*'AP04'!$R18)*'AP04'!$D18 -> 1692.2975 | G18: =(Q17*'AP04'!$R18)/($I$5-A17) -> 838.40276 | H18: =H17 -> 0 | I18: =I17 -> 0 | J18: =J17 -> 25 | K18: =K17 -> 0 | L18: =L17 -> 0 | M18: ='AP03'!D11 -> 2630.36 | N18: =SUM('AP04'!$F18:$L18) -> 2555.7003 | O18: ='AP04'!$M18-'AP04'!$N18 -> 74.659711 | P18: =Q17*('AP04'!$R18-1) -> 0 | Q18: =(Q17*'AP04'!$R18)-'AP04'!$G18-'AP04'!$O18*2 -> 298322.06 | R18: =R17 -> 1
A19: =A18+1 -> 5 | B19: =EDATE(B18,1) -> 43394 | C19: =C18 -> 0.07 | D19: =D18 -> 0.005654 | E19: ='AP04'!$F19+'AP04'!$G19 -> 2524.6963 | F19: =(Q18*'AP04'!$R19)*'AP04'!$D19 -> 1686.7129 | G19: =(Q18*'AP04'!$R19)/($I$5-A18) -> 837.98332 | H19: =H18 -> 0 | I19: =I18 -> 0 | J19: =J18 -> 25 | K19: =K18 -> 0 | L19: =L18 -> 0 | M19: ='AP03'!D12 -> 2625.52 | N19: =SUM('AP04'!$F19:$L19) -> 2549.6963 | O19: ='AP04'!$M19-'AP04'!$N19 -> 75.823728 | P19: =Q18*('AP04'!$R19-1) -> 0 | Q19: =(Q18*'AP04'!$R19)-'AP04'!$G19-'AP04'!$O19*2 -> 297332.43 | R19: =R18 -> 1
A20: =A19+1 -> 6 | B20: =EDATE(B19,1) -> 43425 | C20: =C19 -> 0.07 | D20: =D19 -> 0.005654 | E20: ='AP04'!$F20+'AP04'!$G20 -> 2518.6737 | F20: =(Q19*'AP04'!$R20)*'AP04'!$D20 -> 1681.1176 | G20: =(Q19*'AP04'!$R20)/($I$5-A19) -> 837.55615 | H20: =H19 -> 0 | I20: =I19 -> 0 | J20: =J19 -> 25 | K20: =K19 -> 0 | L20: =L19 -> 0 | M20: ='AP03'!D13 -> 2620.69 | N20: =SUM('AP04'!$F20:$L20) -> 2543.6737 | O20: ='AP04'!$M20-'AP04'!$N20 -> 77.016277 | P20: =Q19*('AP04'!$R20-1) -> 0 | Q20: =(Q19*'AP04'!$R20)-'AP04'!$G20-'AP04'!$O20*2 -> 296340.84 | R20: =R19 -> 1
A21: =A20+1 -> 7 | B21: =EDATE(B20,1) -> 43455 | C21: =C20 -> 0.07 | D21: =D20 -> 0.005654 | E21: ='AP04'!$F21+'AP04'!$G21 -> 2512.6322 | F21: =(Q20*'AP04'!$R21)*'AP04'!$D21 -> 1675.5111 | G21: =(Q20*'AP04'!$R21)/($I$5-A20) -> 837.12103 | H21: =H20 -> 0 | I21: =I20 -> 0 | J21: =J20 -> 25 | K21: =K20 -> 0 | L21: =L20 -> 0 | M21: ='AP03'!D14 -> 2616.41 | N21: =SUM('AP04'!$F21:$L21) -> 2537.6322 | O21: ='AP04'!$M21-'AP04'!$N21 -> 78.77784 | P21: =Q20*('AP04'!$R21-1) -> 0 | Q21: =(Q20*'AP04'!$R21)-'AP04'!$G21-'AP04'!$O21*2 -> 295346.17 | R21: =R20 -> 1
A22: =A21+1 -> 8 | B22: =EDATE(B21,1) -> 43486 | C22: =C21 -> 0.07 | D22: =D21 -> 0.005654 | E22: ='AP04'!$F22+'AP04'!$G22 -> 2506.5619 | F22: =(Q21*'AP04'!$R22)*'AP04'!$D22 -> 1669.8872 | G22: =(Q21*'AP04'!$R22)/($I$5-A21) -> 836.6747 | H22: =H21 -> 0 | I22: =I21 -> 0 | J22: =J21 -> 25 | K22: =K21 -> 0 | L22: =L21 -> 0 | M22: ='AP03'!D15 -> 2611.57 | N22: =SUM('AP04'!$F22:$L22) -> 2531.5619 | O22: ='AP04'!$M22-'AP04'!$N22 -> 80.008075 | P22: =Q21*('AP04'!$R22-1) -> 0 | Q22: =(Q21*'AP04'!$R22)-'AP04'!$G22-'AP04'!$O22*2 -> 294349.48 | R22: =R21 -> 1
A23: =A22+1 -> 9 | B23: =EDATE(B22,1) -> 43517 | C23: =C22 -> 0.07 | D23: =D22 -> 0.005654 | E23: ='AP04'!$F23+'AP04'!$G23 -> 2500.472 | F23: =(Q22*'AP04'!$R23)*'AP04'!$D23 -> 1664.2519 | G23: =(Q22*'AP04'!$R23)/($I$5-A22) -> 836.2201 | H23: =H22 -> 0 | I23: =I22 -> 0 | J23: =J22 -> 25 | K23: =K22 -> 0 | L23: =L22 -> 0 | M23: ='AP03'!D16 -> 2606.73 | N23: =SUM('AP04'!$F23:$L23) -> 2525.472 | O23: ='AP04'!$M23-'AP04'!$N23 -> 81.257956 | P23: =Q22*('AP04'!$R23-1) -> 0 | Q23: =(Q22*'AP04'!$R23)-'AP04'!$G23-'AP04'!$O23*2 -> 293350.74 | R23: =R22 -> 1
A24: =A23+1 -> 10 | B24: =EDATE(B23,1) -> 43545 | C24: =C23 -> 0.07 | D24: =D23 -> 0.005654 | E24: ='AP04'!$F24+'AP04'!$G24 -> 2494.3622 | F24: =(Q23*'AP04'!$R24)*'AP04'!$D24 -> 1658.6051 | G24: =(Q23*'AP04'!$R24)/($I$5-A23) -> 835.7571 | H24: =H23 -> 0 | I24: =I23 -> 0 | J24: =J23 -> 25 | K24: =K23 -> 0 | L24: =L23 -> 0 | M24: ='AP03'!D17 -> 2601.89 | N24: =SUM('AP04'!$F24:$L24) -> 2519.3622 | O24: ='AP04'!$M24-'AP04'!$N24 -> 82.527818 | P24: =Q23*('AP04'!$R24-1) -> 0 | Q24: =(Q23*'AP04'!$R24)-'AP04'!$G24-'AP04'!$O24*2 -> 292349.93 | R24: =R23 -> 1
A25: =A24+1 -> 11 | B25: =EDATE(B24,1) -> 43576 | C25: =C24 -> 0.07 | D25: =D24 -> 0.005654 | E25: ='AP04'!$F25+'AP04'!$G25 -> 2488.232 | F25: =(Q24*'AP04'!$R25)*'AP04'!$D25 -> 1652.9465 | G25: =(Q24*'AP04'!$R25)/($I$5-A24) -> 835.28551 | H25: =H24 -> 0 | I25: =I24 -> 0 | J25: =J24 -> 25 | K25: =K24 -> 0 | L25: =L24 -> 0 | M25: ='AP03'!D18 -> 2597.05 | N25: =SUM('AP04'!$F25:$L25) -> 2513.232 | O25: ='AP04'!$M25-'AP04'!$N25 -> 83.818001 | P25: =Q24*('AP04'!$R25-1) -> 0 | Q25: =(Q24*'AP04'!$R25)-'AP04'!$G25-'AP04'!$O25*2 -> 291347.01 | R25: =R24 -> 1
A26: =A25+1 -> 12 | B26: =EDATE(B25,1) -> 43606 | C26: =C25 -> 0.07 | D26: =D25 -> 0.005654 | E26: ='AP04'!$F26+'AP04'!$G26 -> 2482.0811 | F26: =(Q25*'AP04'!$R26)*'AP04'!$D26 -> 1647.276 | G26: =(Q25*'AP04'!$R26)/($I$5-A25) -> 834.80518 | H26: =H25 -> 0 | I26: =I25 -> 0 | J26: =J25 -> 25 | K26: =K25 -> 0 | L26: =L25 -> 0 | M26: ='AP03'!D19 -> 2592.21 | N26: =SUM('AP04'!$F26:$L26) -> 2507.0811 | O26: ='AP04'!$M26-'AP04'!$N26 -> 85.128851 | P26: =Q25*('AP04'!$R26-1) -> 0 | Q26: =(Q25*'AP04'!$R26)-'AP04'!$G26-'AP04'!$O26*2 -> 290341.94 | R26: =R25 -> 1
A27: =A26+1 -> 13 | B27: =EDATE(B26,1) -> 43637 | C27: =C26 -> 0.07 | D27: =D26 -> 0.005654 | E27: ='AP04'!$F27+'AP04'!$G27 -> 2475.9093 | F27: =(Q26*'AP04'!$R27)*'AP04'!$D27 -> 1641.5933 | G27: =(Q26*'AP04'!$R27)/($I$5-A26) -> 834.31593 | H27: =H26 -> 0 | I27: =I26 -> 0 | J27: =J26 -> 25 | K27: =K26 -> 0 | L27: =L26 -> 0 | M27: ='AP03'!D20 -> 2587.38 | N27: =SUM('AP04'!$F27:$L27) -> 2500.9093 | O27: ='AP04'!$M27-'AP04'!$N27 -> 86.470723 | P27: =Q26*('AP04'!$R27-1) -> 0 | Q27: =(Q26*'AP04'!$R27)-'AP04'!$G27-'AP04'!$O27*2 -> 289334.69 | R27: =R26 -> 1
... A35: =A34+1 -> 21 | B35: =EDATE(B34,1) -> 43882 | C35: =C34 -> 0.07 | D35: =D34 -> 0.005654 | E35: ='AP04'!$F35+'AP04'!$G35 -> 2425.7091 | F35: =(Q34*'AP04'!$R35)*'AP04'!$D35 -> 1595.6577 | G35: =(Q34*'AP04'!$R35)/($I$5-A34) -> 830.05144 | H35: =H34 -> 0 | I35: =I34 -> 0 | J35: =J34 -> 25 | K35: =K34 -> 0 | L35: =L34 -> 0 | M35: ='AP03'!D28 -> 2558.55 | N35: =SUM('AP04'!$F35:$L35) -> 2450.7091 | O35: ='AP04'!$M35-'AP04'!$N35 -> 107.84086 | P35: =Q34*('AP04'!$R35-1) -> 0 | Q35: =(Q34*'AP04'!$R35)-'AP04'!$G35-'AP04'!$O35*2 -> 281171.76 | R35: =R34 -> 1
A36: =A35+1 -> 22 | B36: =EDATE(B35,1) -> 43911 | C36: 0.062 | D36: 0.005025 | E36: ='AP04'!$F36+'AP04'!$G36 -> 2242.3033 | F36: =(Q35*'AP04'!$R36)*'AP04'!$D36 -> 1412.8881 | G36: =(Q35*'AP04'!$R36)/($I$5-A35) -> 829.41522 | H36: =H35 -> 0 | I36: =I35 -> 0 | J36: =J35 -> 25 | K36: =K35 -> 0 | L36: =L35 -> 0 | M36: ='AP03'!D29 -> 2374.56 | N36: =SUM('AP04'!$F36:$L36) -> 2267.3033 | O36: ='AP04'!$M36-'AP04'!$N36 -> 107.2567 | P36: =Q35*('AP04'!$R36-1) -> 0 | Q36: =(Q35*'AP04'!$R36)-'AP04'!$G36-'AP04'!$O36*2 -> 280127.83 | R36: =R35 -> 1
A37: =A36+1 -> 23 | B37: =EDATE(B36,1) -> 43942 | C37: 0.062 | D37: =D36 -> 0.005025 | E37: ='AP04'!$F37+'AP04'!$G37 -> 2236.4229 | F37: =(Q36*'AP04'!$R37)*'AP04'!$D37 -> 1407.6423 | G37: =(Q36*'AP04'!$R37)/($I$5-A36) -> 828.78056 | H37: =H36 -> 0 | I37: =I36 -> 0 | J37: =J36 -> 25 | K37: =K36 -> 0 | L37: =L36 -> 0 | M37: ='AP03'!D30 -> 2370.23 | N37: =SUM('AP04'!$F37:$L37) -> 2261.4229 | O37: ='AP04'!$M37-'AP04'!$N37 -> 108.8071 | P37: =Q36*('AP04'!$R37-1) -> 0 | Q37: =(Q36*'AP04'!$R37)-'AP04'!$G37-'AP04'!$O37*2 -> 279081.43 | R37: =R36 -> 1
A38: =A37+1 -> 24 | B38: =EDATE(B37,1) -> 43972 | C38: 0.062 | D38: =D37 -> 0.005025 | E38: ='AP04'!$F38+'AP04'!$G38 -> 2230.519 | F38: =(Q37*'AP04'!$R38)*'AP04'!$D38 -> 1402.3842 | G38: =(Q37*'AP04'!$R38)/($I$5-A37) -> 828.13482 | H38: =H37 -> 0 | I38: =I37 -> 0 | J38: =J37 -> 25 | K38: =K37 -> 0 | L38: =L37 -> 0 | M38: ='AP03'!D31 -> 2365.89 | N38: =SUM('AP04'!$F38:$L38) -> 2255.519 | O38: ='AP04'!$M38-'AP04'!$N38 -> 110.37097 | P38: =Q37*('AP04'!$R38-1) -> 0 | Q38: =(Q37*'AP04'!$R38)-'AP04'!$G38-'AP04'!$O38*2 -> 278032.56 | R38: =R37 -> 1
A39: =A38+1 -> 25 | B39: =EDATE(B38,1) -> 44003 | C39: 0.062 | D39: =D38 -> 0.005025 | E39: ='AP04'!$F39+'AP04'!$G39 -> 2224.5915 | F39: =(Q38*'AP04'!$R39)*'AP04'!$D39 -> 1397.1136 | G39: =(Q38*'AP04'!$R39)/($I$5-A38) -> 827.47785 | H39: =H38 -> 0 | I39: =I38 -> 0 | J39: =J38 -> 25 | K39: =K38 -> 0 | L39: =L38 -> 0 | M39: ='AP03'!D32 -> 2361.55 | N39: =SUM('AP04'!$F39:$L39) -> 2249.5915 | O39: ='AP04'!$M39-'AP04'!$N39 -> 111.95855 | P39: =Q38*('AP04'!$R39-1) -> 0 | Q39: =(Q38*'AP04'!$R39)-'AP04'!$G39-'AP04'!$O39*2 -> 276981.16 | R39: =R38 -> 1
A40: =A39+1 -> 26 | B40: =EDATE(B39,1) -> 44033 | C40: 0.062 | D40: =D39 -> 0.005025 | E40: ='AP04'!$F40+'AP04'!$G40 -> 2218.6398 | F40: =(Q39*'AP04'!$R40)*'AP04'!$D40 -> 1391.8303 | G40: =(Q39*'AP04'!$R40)/($I$5-A39) -> 826.80944 | H40: =H39 -> 0 | I40: =I39 -> 0 | J40: =J39 -> 25 | K40: =K39 -> 0 | L40: =L39 -> 0 | M40: ='AP03'!D33 -> 2357.21 | N40: =SUM('AP04'!$F40:$L40) -> 2243.6398 | O40: ='AP04'!$M40-'AP04'!$N40 -> 113.57021 | P40: =Q39*('AP04'!$R40-1) -> 0 | Q40: =(Q39*'AP04'!$R40)-'AP04'!$G40-'AP04'!$O40*2 -> 275927.21 | R40: =R39 -> 1
A41: =A40+1 -> 27 | B41: =EDATE(B40,1) -> 44064 | C41: 0.062 | D41: =D40 -> 0.005025 | E41: ='AP04'!$F41+'AP04'!$G41 -> 2212.6636 | F41: =(Q40*'AP04'!$R41)*'AP04'!$D41 -> 1386.5342 | G41: =(Q40*'AP04'!$R41)/($I$5-A40) -> 826.12938 | H41: =H40 -> 0 | I41: =I40 -> 0 | J41: =J40 -> 25 | K41: =K40 -> 0 | L41: =L40 -> 0 | M41: ='AP03'!D34 -> 2352.88 | N41: =SUM('AP04'!$F41:$L41) -> 2237.6636 | O41: ='AP04'!$M41-'AP04'!$N41 -> 115.21637 | P41: =Q40*('AP04'!$R41-1) -> 0 | Q41: =(Q40*'AP04'!$R41)-'AP04'!$G41-'AP04'!$O41*2 -> 274870.65 | R41: =R40 -> 1
A42: =A41+1 -> 28 | B42: =EDATE(B41,1) -> 44095 | C42: =C41 -> 0.062 | D42: =D41 -> 0.005025 | E42: ='AP04'!$F42+'AP04'!$G42 -> 2206.6624 | F42: =(Q41*'AP04'!$R42)*'AP04'!$D42 -> 1381.225 | G42: =(Q41*'AP04'!$R42)/($I$5-A41) -> 825.43739 | H42: =H41 -> 0 | I42: =I41 -> 0 | J42: =J41 -> 25 | K42: =K41 -> 0 | L42: =L41 -> 0 | M42: ='AP03'!D35 -> 2348.54 | N42: =SUM('AP04'!$F42:$L42) -> 2231.6624 | O42: ='AP04'!$M42-'AP04'!$N42 -> 116.87759 | P42: =Q41*('AP04'!$R42-1) -> 0 | Q42: =(Q41*'AP04'!$R42)-'AP04'!$G42-'AP04'!$O42*2 -> 273811.46 | R42: =R41 -> 1
A43: =A42+1 -> 29 | B43: =EDATE(B42,1) -> 44125 | C43: =C42 -> 0.062 | D43: =D42 -> 0.005025 | E43: ='AP04'!$F43+'AP04'!$G43 -> 2200.6359 | F43: =(Q42*'AP04'!$R43)*'AP04'!$D43 -> 1375.9026 | G43: =(Q42*'AP04'!$R43)/($I$5-A42) -> 824.73331 | H43: =H42 -> 0 | I43: =I42 -> 0 | J43: =J42 -> 25 | K43: =K42 -> 0 | L43: =L42 -> 0 | M43: ='AP03'!D36 -> 2344.34 | N43: =SUM('AP04'!$F43:$L43) -> 2225.6359 | O43: ='AP04'!$M43-'AP04'!$N43 -> 118.70411 | P43: =Q42*('AP04'!$R43-1) -> 0 | Q43: =(Q42*'AP04'!$R43)-'AP04'!$G43-'AP04'!$O43*2 -> 272749.32 | R43: =R42 -> 1
A44: =A43+1 -> 30 | B44: =EDATE(B43,1) -> 44156 | C44: =C43 -> 0.062 | D44: =D43 -> 0.005025 | E44: ='AP04'!$F44+'AP04'!$G44 -> 2194.5814 | F44: =(Q43*'AP04'!$R44)*'AP04'!$D44 -> 1370.5653 | G44: =(Q43*'AP04'!$R44)/($I$5-A43) -> 824.01606 | H44: =H43 -> 0 | I44: =I43 -> 0 | J44: =J43 -> 25 | K44: =K43 -> 0 | L44: =L43 -> 0 | M44: ='AP03'!D37 -> 2340 | N44: =SUM('AP04'!$F44:$L44) -> 2219.5814 | O44: ='AP04'!$M44-'AP04'!$N44 -> 120.41862 | P44: =Q43*('AP04'!$R44-1) -> 0 | Q44: =(Q43*'AP04'!$R44)-'AP04'!$G44-'AP04'!$O44*2 -> 271684.46 | R44: =R43 -> 1
A45: =A44+1 -> 31 | B45: =EDATE(B44,1) -> 44186 | C45: =C44 -> 0.062 | D45: =D44 -> 0.005025 | E45: ='AP04'!$F45+'AP04'!$G45 -> 2188.5007 | F45: =(Q44*'AP04'!$R45)*'AP04'!$D45 -> 1365.2144 | G45: =(Q44*'AP04'!$R45)/($I$5-A44) -> 823.28625 | H45: =H44 -> 0 | I45: =I44 -> 0 | J45: =J44 -> 25 | K45: =K44 -> 0 | L45: =L44 -> 0 | M45: ='AP03'!D38 -> 2336.59 | N45: =SUM('AP04'!$F45:$L45) -> 2213.5007 | O45: ='AP04'!$M45-'AP04'!$N45 -> 123.08932 | P45: =Q44*('AP04'!$R45-1) -> 0 | Q45: =(Q44*'AP04'!$R45)-'AP04'!$G45-'AP04'!$O45*2 -> 270615 | R45: =R44 -> 1
A46: =A45+1 -> 32 | B46: =EDATE(B45,1) -> 44217 | C46: =C45 -> 0.062 | D46: =D45 -> 0.005025 | E46: ='AP04'!$F46+'AP04'!$G46 -> 2182.3784 | F46: =(Q45*'AP04'!$R46)*'AP04'!$D46 -> 1359.8404 | G46: =(Q45*'AP04'!$R46)/($I$5-A45) -> 822.53799 | H46: =H45 -> 0 | I46: =I45 -> 0 | J46: =J45 -> 25 | K46: =K45 -> 0 | L46: =L45 -> 0 | M46: ='AP03'!D39 -> 2332.25 | N46: =SUM('AP04'!$F46:$L46) -> 2207.3784 | O46: ='AP04'!$M46-'AP04'!$N46 -> 124.87164 | P46: =Q45*('AP04'!$R46-1) -> 0 | Q46: =(Q45*'AP04'!$R46)-'AP04'!$G46-'AP04'!$O46*2 -> 269542.72 | R46: =R45 -> 1
A47: =A46+1 -> 33 | B47: =EDATE(B46,1) -> 44248 | C47: =C46 -> 0.062 | D47: =D46 -> 0.005025 | E47: ='AP04'!$F47+'AP04'!$G47 -> 2176.2287 | F47: =(Q46*'AP04'!$R47)*'AP04'!$D47 -> 1354.4522 | G47: =(Q46*'AP04'!$R47)/($I$5-A46) -> 821.77658 | H47: =H46 -> 0 | I47: =I46 -> 0 | J47: =J46 -> 25 | K47: =K46 -> 0 | L47: =L46 -> 0 | M47: ='AP03'!D40 -> 2328.53 | N47: =SUM('AP04'!$F47:$L47) -> 2201.2287 | O47: ='AP04'!$M47-'AP04'!$N47 -> 127.30127 | P47: =Q46*('AP04'!$R47-1) -> 0 | Q47: =(Q46*'AP04'!$R47)-'AP04'!$G47-'AP04'!$O47*2 -> 268466.34 | R47: =R46 -> 1
A48: =A47+1 -> 34 | B48: =EDATE(B47,1) -> 44276 | C48: =C47 -> 0.062 | D48: =D47 -> 0.005025 | E48: ='AP04'!$F48+'AP04'!$G48 -> 2170.0413 | F48: =(Q47*'AP04'!$R48)*'AP04'!$D48 -> 1349.0433 | G48: =(Q47*'AP04'!$R48)/($I$5-A47) -> 820.99798 | H48: =H47 -> 0 | I48: =I47 -> 0 | J48: =J47 -> 25 | K48: =K47 -> 0 | L48: =L47 -> 0 | M48: ='AP03'!D41 -> 2324.19 | N48: =SUM('AP04'!$F48:$L48) -> 2195.0413 | O48: ='AP04'!$M48-'AP04'!$N48 -> 129.14867 | P48: =Q47*('AP04'!$R48-1) -> 0 | Q48: =(Q47*'AP04'!$R48)-'AP04'!$G48-'AP04'!$O48*2 -> 267387.04 | R48: =R47 -> 1
A49: =A48+1 -> 35 | B49: =EDATE(B48,1) -> 44307 | C49: =C48 -> 0.062 | D49: =D48 -> 0.005025 | E49: ='AP04'!$F49+'AP04'!$G49 -> 2163.8255 | F49: =(Q48*'AP04'!$R49)*'AP04'!$D49 -> 1343.6199 | G49: =(Q48*'AP04'!$R49)/($I$5-A48) -> 820.20565 | H49: =H48 -> 0 | I49: =I48 -> 0 | J49: =J48 -> 25 | K49: =K48 -> 0 | L49: =L48 -> 0 | M49: ='AP03'!D42 -> 2319.85 | N49: =SUM('AP04'!$F49:$L49) -> 2188.8255 | O49: ='AP04'!$M49-'AP04'!$N49 -> 131.02446 | P49: =Q48*('AP04'!$R49-1) -> 0 | Q49: =(Q48*'AP04'!$R49)-'AP04'!$G49-'AP04'!$O49*2 -> 266304.79 | R49: =R48 -> 1
...

Sheet AP05
A1: APÊNDICE 05: EVOLUÇÃO DO FINANCIAMENTO COM TAXA MÉDIA E EXPURGO DOS SEGUROS => COM REST. SIMPLES
A3: ='AP01'!A3 -> Requerente: ADRIANA MELO DE OLIVEIRA
A4: ='AP01'!A4 -> Requerido: ITAÚ UNIBANCO
A5: Valor do Bem | D5: ='AP01'!D5 -> 432000 | F5: Qtde Prestações | I5: ='AP01'!I5 -> 360
A6: Entrada/Descontos | D6: ='AP01'!D6 -> 129600 | F6: Taxa MÉDIA Efetiva (a.m.) | I6: 0.0062
A7: Valor Financiado | D7: =D5-D6 -> 302400 | F7: Taxa MÉDIA Efetiva (a.a.) | I7: 0.0775
A8: Data do Contrato | D8: ='AP01'!D8 -> 43241 | F8: Taxa de Juros Efetiva (a.a.) | I8: ='AP01'!I7 -> 0.117
A9: 1° Vencimento | D9: ='AP01'!D9 -> 43272 | F9: (%) Excesso Taxa Média | I9: =(I8/I7)-1 -> 0.50967742
A10: Sistema de Amortização | D10: ='AP01'!D10 -> SAC | F10: Prestação Mensal | I10: ='AP01'!I10 -> 2549.8136
